Workbook
Name CRF: #REF!
Name DiscountRate: #REF!
Name FacilityLifetime: #REF!
Name GeneralDataManufacturingLocations: #REF!
Name MaterialData316SSStandardDensity: #REF!
Name MaterialDataA36CSStandardDensity: #REF!
Name MaterialDataB4CNaturalTheoreticalDensity: #REF!
Name MaterialDataConcreteNominalSolidDensity: #REF!
Name MaterialDataGeneralInsulationStandardDensity: #REF!
Name MaterialDataGR22StandardDensity: #REF!
Name MaterialDataInconel718StandardDensity: #REF!
Name UC_m_in: #REF!

Sheet Cost Database
A1: Account | B1: Level | C1: Account Name | D1: Account Title | E1: Standard Cost Equation? | F1: Optional Variable | G1: Optional Value | H1: Sec Optional Variable | I1: Sec Optional Value | J1: Fixed Cost ($) | K1: Unit Cost | L1: Unit Cost (units) | M1: Scaling Variable | N1: Scaling Variable Ref Value | O1: Units | P1: Exponent | Q1: Dollar Year | R1: Type | S1: Source | T1: Ref | U1: Link | V1: Notes | W1: FOAK to NOAK Multiplier Type | X1: Fixed Cost Low End | Y1: Fixed Cost High End | Z1: Fixed Cost Distribution | AA1: Unit Cost Low End | AB1: Unit Cost High End | AC1: Unit Cost Distribution | AD1: Exponent std | AE1: Exponent Max | AF1: Exponent Min | AG1: Exponent Distribution
A2: 10 | B2: 0 | C2: Capitalized Pre-Construction Costs | D2: =REPT(" ", B2*2) & C2
A3: 11 | B3: 1 | C3: Land Cost | D3: =REPT(" ", B3*2) & C3 | E3: standard | K3: 3800 | L3: $/acres | M3: Land Area | O3: acres | Q3: 2022 | R3: General | S3: The average cost per acre for rural land in 2022 from the US Department of Agriculture | T3: Abou-Jaoude, A., Lohse, C. S., Larsen, L. M., Guaita, N., Trivedi, I., Joseck, F. C., ... & Stein, A. (2024). Meta-analysis of advanced nuclear reactor cost estimations (No. INL/RPT-24-77048-Rev001). Idaho National Laboratory (INL), Idaho Falls, ID (United States). | U3: https://inldigitallibrary.inl.gov/sites/sti/sti/Sort_107010.pdf | W3: No Learning | X3: =0.9*$J3 | Y3: =1.5*J3 | Z3: Lognormal | AA3: =0.9*K3 | AB3: =1.3*K3 | AC3: Lognormal | AD3: 0.1 | AE3: 1 | AF3: 0 | AG3: Truncated Normal
A4: 12 | B4: 1 | C4: Site Permits | D4: =REPT(" ", B4*2) & C4 | E4: standard | K4: =10.03*1000 | L4: $/MWe | M4: Power MWe | O4: MWe | Q4: 2022 | R4: Labor | S4: Data from SMR MHTGRs | W4: No Learning | X4: =0.9*$J4 | Y4: =1.5*J4 | Z4: Lognormal | AA4: =0.9*K4 | AB4: =1.3*K4 | AC4: Lognormal | AD4: 0.1 | AE4: 1 | AF4: 0 | AG4: Truncated Normal
A5: 13 | B5: 1 | C5: Plant Licensing | D5: =REPT(" ", B5*2) & C5 | E5: standard | J5: =0.5*(X5+Y5) | Q5: 2024 | R5: Labor | S5: NRC Website | T5: Using data from the NRC website that the cost is between 45 and 70M https://www.nrc.gov/about-nrc/regulatory/licensing/general-fee-questions.pdf Also, using recent change to the NRC fees by a factor of 0.47 https://ignition-news.com/the-nrc-passes-new-rules-for-advanced-reactor-companies/#:~:text=Under%20a%20rule%20published%20in,2024%2C%20which%20takes%20effect%20Oct. | U5: https://art.inl.gov/NGNP/INL%20Documents/Year%202012/Assessment%20of%20High%20Temperature%20Gas-Cooled%20Reactor%20-%20HTGR%20-%20Capital%20and%20Operating%20Costs.pdf | W5: Licensing Learning | X5: =0.47*45*1000000 | Y5: =0.47*70*1000000 | Z5: Uniform | AA5: =0.9*K5 | AB5: =1.3*K5 | AC5: Lognormal | AD5: 0.1 | AE5: 1 | AF5: 0 | AG5: Truncated Normal
A6: 14 | B6: 1 | C6: Plant Permits | D6: =REPT(" ", B6*2) & C6 | E6: standard | J6: 3000000 | Q6: 2009 | R6: Labor | S6: NGNP project | T6: Gandrik, A., B. Wallace, L. Demick, S. Melancon and M. Patterson (2011). "Assessment of high temperature gas-cooled reactor (HTGR) capital and operating costs." Idaho National Laboratory, TEV-1196, Idaho Falls, ID. | W6: No Learning | X6: =0.9*$J6 | Y6: =1.5*J6 | Z6: Lognormal | AA6: =0.9*K6 | AB6: =1.3*K6 | AC6: Lognormal | AD6: 0.1 | AE6: 1 | AF6: 0 | AG6: Truncated Normal
A7: 15 | B7: 1 | C7: Plant Studies | D7: =REPT(" ", B7*2) & C7 | E7: standard | J7: =MARVEL_Cost!C4 | Q7: 2024 | R7: Labor | S7: MARVEL Project (Labor-adjusted Cost) | T7: Hanna, B. N., Gonzaga de Oliveira, R. G., Mohammad Al Dawood, K. A., Patterson, M. D., Abou Jaoude, A., & Garcia, S. (2024). Technoeconomic Evaluation of Microreactor Using Detailed Bottom-up Estimate (No. INL/RPT-24-80433-Rev000). Idaho National Laboratory (INL), Idaho Falls, ID (United States). | U7: https://inldigitallibrary.inl.gov/sites/sti/sti/Sort_129862.pdf | V7: MARVEL's data were updated | W7: No Learning | X7: =0.9*$J7 | Y7: =1.5*J7 | Z7: Lognormal | AA7: =0.9*K7 | AB7: =1.3*K7 | AC7: Lognormal | AD7: 0.1 | AE7: 1 | AF7: 0 | AG7: Truncated Normal
A8: 20 | B8: 0 | C8: Capitalized Direct Costs | D8: =REPT(" ", B8*2) & C8
A9: 21 | B9: 1 | C9: Structures and Improvements | D9: =REPT(" ", B9*2) & C9
A10: 211 | B10: 2 | C10: Site Preparation/ Yard Work | D10: =REPT(" ", B10*2) & C10
A11: 211.1 | B11: 3 | C11: Cleaning and Grubbing | D11: =REPT(" ", B11*2) & C11 | E11: standard | K11: =4408.18*1.33 | L11: $/acres | M11: Land Area | O11: acres | Q11: 2024 | R11: Lab and Equip | S11: RSMeans software: a tool that primarily provides costs for non-nuclear work Nuclear Multiplier have been applied to adjust the costs for nuclear-site-related work | T11: GORDIAN. (2024). "RSMeans data. & Delene, J. G. and I. Hudson, C. R. (1993). Cost estimate guidelines for advanced nuclear power technologies. United States, Oak Ridge National Lab. (ORNL), Oak Ridge, TN (United States): Medium: ED; Size: 159 p. | U11: https://www.rsmeans.com/ & https://www.osti.gov/biblio/10176857 | W11: Onsite Learning | X11: =0.9*$J11 | Y11: =1.5*J11 | Z11: Lognormal | AA11: =0.9*K11 | AB11: =1.3*K11 | AC11: Lognormal | AD11: 0.1 | AE11: 1 | AF11: 0 | AG11: Truncated Normal
A12: 211.2 | B12: 3 | C12: Stripping Topsoil | D12: =REPT(" ", B12*2) & C12 | E12: standard | K12: =2565.2*1.33 | L12: $/acres | M12: Land Area | O12: acres | Q12: 2024 | R12: Lab and Equip | W12: Onsite Learning | X12: =0.9*$J12 | Y12: =1.5*J12 | Z12: Lognormal | AA12: =0.9*K12 | AB12: =1.3*K12 | AC12: Lognormal | AD12: 0.1 | AE12: 1 | AF12: 0 | AG12: Truncated Normal
A13: 211.3 | B13: 3 | C13: Excavation | D13: =REPT(" ", B13*2) & C13 | E13: standard | K13: =22.86*1.4 | L13: $/m^3 | M13: Excavation Volume | O13: m^3 | Q13: 2024 | R13: Lab and Equip | W13: Onsite Learning | X13: =0.9*$J13 | Y13: =1.5*J13 | Z13: Lognormal | AA13: =0.9*K13 | AB13: =1.3*K13 | AC13: Lognormal | AD13: 0.1 | AE13: 1 | AF13: 0 | AG13: Truncated Normal
A14: 212 | B14: =IF(ISNUMBER(A14), IF(AND(A14=INT(A14), MOD(A14, 10) = 0), 0, IF(AND(A14=INT(A14), LEN(A14)=2), 1, IF(AND(A14=INT(A14), LEN(A14)=3), 2, LEN(A14) - FIND(".", A14) + 2) ) ), "") | C14: Reactor Island Civil Structures | D14: =REPT(" ", B14*2) & C14
A15: 212.1 | B15: =IF(ISNUMBER(A15), IF(AND(A15=INT(A15), MOD(A15, 10) = 0), 0, IF(AND(A15=INT(A15), LEN(A15)=2), 1, IF(AND(A15=INT(A15), LEN(A15)=3), 2, LEN(A15) - FIND(".", A15) + 2) ) ), "") | C15: Reactor Building Slab Roof | D15: =REPT(" ", B15*2) & C15 | E15: standard | K15: =1200 *1.53 | L15: $/m^3 | M15: Reactor Building Slab Roof Volume | O15: m^3 | Q15: 2024 | R15: Lab and Mat and Equip | S15: RSMeans software: a tool that primarily provides costs for non-nuclear work Nuclear Multiplier have been applied to adjust the costs for nuclear-site-related work | T15: GORDIAN. (2024). "RSMeans data. & Delene, J. G. and I. Hudson, C. R. (1993). Cost estimate guidelines for advanced nuclear power technologies. United States, Oak Ridge National Lab. (ORNL), Oak Ridge, TN (United States): Medium: ED; Size: 159 p. | U15: https://www.rsmeans.com/ & https://www.osti.gov/biblio/10176857 | W15: Onsite Learning | X15: =0.9*$J15 | Y15: =1.5*J15 | Z15: Lognormal | AA15: =0.9*K15 | AB15: =1.3*K15 | AC15: Lognormal | AD15: 0.1 | AE15: 1 | AF15: 0 | AG15: Truncated Normal
A16: 212.2 | B16: =IF(ISNUMBER(A16), IF(AND(A16=INT(A16), MOD(A16, 10) = 0), 0, IF(AND(A16=INT(A16), LEN(A16)=2), 1, IF(AND(A16=INT(A16), LEN(A16)=3), 2, LEN(A16) - FIND(".", A16) + 2) ) ), "") | C16: Reactor Building Basement | D16: =REPT(" ", B16*2) & C16 | E16: standard | K16: =943.9*1.53 | L16: $/m^3 | M16: Reactor Building Basement Volume | O16: m^3 | Q16: 2024 | R16: Lab and Mat and Equip | W16: Onsite Learning | X16: =0.9*$J16 | Y16: =1.5*J16 | Z16: Lognormal | AA16: =0.9*K16 | AB16: =1.3*K16 | AC16: Lognormal | AD16: 0.1 | AE16: 1 | AF16: 0 | AG16: Truncated Normal
A17: 212.3 | B17: =IF(ISNUMBER(A17), IF(AND(A17=INT(A17), MOD(A17, 10) = 0), 0, IF(AND(A17=INT(A17), LEN(A17)=2), 1, IF(AND(A17=INT(A17), LEN(A17)=3), 2, LEN(A17) - FIND(".", A17) + 2) ) ), "") | C17: Reactor Building Walls | D17: =REPT(" ", B17*2) & C17 | E17: standard | K17: =721.21*1.53 | L17: $/m^3 | M17: Reactor Building Exterior Walls Volume | O17: m^3 | Q17: 2024 | R17: Lab and Mat and Equip | W17: Onsite Learning | X17: =0.9*$J17 | Y17: =1.5*J17 | Z17: Lognormal | AA17: =0.9*K17 | AB17: =1.3*K17 | AC17: Lognormal | AD17: 0.1 | AE17: 1 | AF17: 0 | AG17: Truncated Normal
A18: 212.4 | B18: =IF(ISNUMBER(A18), IF(AND(A18=INT(A18), MOD(A18, 10) = 0), 0, IF(AND(A18=INT(A18), LEN(A18)=2), 1, IF(AND(A18=INT(A18), LEN(A18)=3), 2, LEN(A18) - FIND(".", A18) + 2) ) ), "") | C18: Reactor Building Liner | D18: =REPT(" ", B18*2) & C18 | E18: standard | K18: =60848829/9373 | L18: $/m^2 | M18: Reactor Building Superstructure Area | N18: 9373 | O18: m^2 | P18: 1 | Q18: 2018 | R18: Lab and Mat and Equip | S18: Stewart W.R., Shirvan K., "Capital cost estimation for advanced nuclear power plants," Renewable and Sustainable Energy Reviews, Nov. 2021, 111880 | T18: Stewart W.R., Shirvan K., "Capital cost estimation for advanced nuclear power plants," Renewable and Sustainable Energy Reviews, Nov. 2021, 111880 | U18: https://doi.org/10.1016/j.rser.2021.111880 | W18: Onsite Learning | X18: =0.9*$J18 | Y18: =1.5*J18 | Z18: Lognormal | AA18: =0.9*K18 | AB18: =1.3*K18 | AC18: Lognormal | AD18: 0.1 | AE18: 1 | AF18: 0 | AG18: Truncated Normal
A19: 212.5 | B19: =IF(ISNUMBER(A19), IF(AND(A19=INT(A19), MOD(A19, 10) = 0), 0, IF(AND(A19=INT(A19), LEN(A19)=2), 1, IF(AND(A19=INT(A19), LEN(A19)=3), 2, LEN(A19) - FIND(".", A19) + 2) ) ), "") | C19: Reactor Building HVAC | D19: =REPT(" ", B19*2) & C19 | E19: standard | K19: =5917967/N19 | L19: $/MWt | M19: Power MWt | N19: 3417 | O19: MWt | P19: 0.8 | Q19: 2018 | R19: Lab and Mat and Equip | S19: Stewart W.R., Shirvan K., "Capital cost estimation for advanced nuclear power plants," Renewable and Sustainable Energy Reviews, Nov. 2021, 111880 | T19: Stewart W.R., Shirvan K., "Capital cost estimation for advanced nuclear power plants," Renewable and Sustainable Energy Reviews, Nov. 2021, 111880 | U19: https://doi.org/10.1016/j.rser.2021.111880 | W19: Onsite Learning | X19: =0.9*$J19 | Y19: =1.5*J19 | Z19: Lognormal | AA19: =0.9*K19 | AB19: =1.3*K19 | AC19: Lognormal | AD19: 0.1 | AE19: 1 | AF19: 0 | AG19: Truncated Normal
A20: 213 | B20: =IF(ISNUMBER(A20), IF(AND(A20=INT(A20), MOD(A20, 10) = 0), 0, IF(AND(A20=INT(A20), LEN(A20)=2), 1, IF(AND(A20=INT(A20), LEN(A20)=3), 2, LEN(A20) - FIND(".", A20) + 2) ) ), "") | C20: Main Function Buildings | D20: =REPT(" ", B20*2) & C20
A21: 213.1 | B21: =IF(ISNUMBER(A21), IF(AND(A21=INT(A21), MOD(A21, 10) = 0), 0, IF(AND(A21=INT(A21), LEN(A21)=2), 1, IF(AND(A21=INT(A21), LEN(A21)=3), 2, LEN(A21) - FIND(".", A21) + 2) ) ), "") | C21: Energy conversion Building | D21: =REPT(" ", B21*2) & C21
A22: 213.11 | B22: =IF(ISNUMBER(A22), IF(AND(A22=INT(A22), MOD(A22, 10) = 0), 0, IF(AND(A22=INT(A22), LEN(A22)=2), 1, IF(AND(A22=INT(A22), LEN(A22)=3), 2, LEN(A22) - FIND(".", A22) + 2) ) ), "") | C22: Energy Conversion Building Slab Roof | D22: =REPT(" ", B22*2) & C22 | E22: standard | K22: =1200 | L22: $/m^3 | M22: Turbine Building Slab Roof Volume | O22: m^3 | Q22: 2024 | R22: Lab and Mat and Equip | S22: RSMeans software: a tool that primarily provides costs for non-nuclear work | T22: GORDIAN. (2024). "RSMeans data. & Delene, J. G. and I. Hudson, C. R. (1993). Cost estimate guidelines for advanced nuclear power technologies. United States, Oak Ridge National Lab. (ORNL), Oak Ridge, TN (United States): Medium: ED; Size: 159 p. | U22: https://www.rsmeans.com/ & https://www.osti.gov/biblio/10176857 | W22: Onsite Learning | X22: =0.9*$J22 | Y22: =1.5*J22 | Z22: Lognormal | AA22: =0.9*K22 | AB22: =1.3*K22 | AC22: Lognormal | AD22: 0.1 | AE22: 1 | AF22: 0 | AG22: Truncated Normal
A23: 213.12 | B23: =IF(ISNUMBER(A23), IF(AND(A23=INT(A23), MOD(A23, 10) = 0), 0, IF(AND(A23=INT(A23), LEN(A23)=2), 1, IF(AND(A23=INT(A23), LEN(A23)=3), 2, LEN(A23) - FIND(".", A23) + 2) ) ), "") | C23: Energy Conversion Building Basement | D23: =REPT(" ", B23*2) & C23 | E23: standard | K23: =943.9 | L23: $/m^3 | M23: Turbine Building Basement Volume | O23: m^3 | Q23: 2024 | R23: Lab and Mat and Equip | W23: Onsite Learning | X23: =0.9*$J23 | Y23: =1.5*J23 | Z23: Lognormal | AA23: =0.9*K23 | AB23: =1.3*K23 | AC23: Lognormal | AD23: 0.1 | AE23: 1 | AF23: 0 | AG23: Truncated Normal
A24: 213.13 | B24: =IF(ISNUMBER(A24), IF(AND(A24=INT(A24), MOD(A24, 10) = 0), 0, IF(AND(A24=INT(A24), LEN(A24)=2), 1, IF(AND(A24=INT(A24), LEN(A24)=3), 2, LEN(A24) - FIND(".", A24) + 2) ) ), "") | C24: Energy Conversion Building Walls | D24: =REPT(" ", B24*2) & C24 | E24: standard | K24: =721.21 | L24: $/m^3 | M24: Turbine Building Exterior Walls Volume | O24: m^3 | Q24: 2024 | R24: Lab and Mat and Equip | W24: Onsite Learning | X24: =0.9*$J24 | Y24: =1.5*J24 | Z24: Lognormal | AA24: =0.9*K24 | AB24: =1.3*K24 | AC24: Lognormal | AD24: 0.1 | AE24: 1 | AF24: 0 | AG24: Truncated Normal
A25: 213.2 | B25: =IF(ISNUMBER(A25), IF(AND(A25=INT(A25), MOD(A25, 10) = 0), 0, IF(AND(A25=INT(A25), LEN(A25)=2), 1, IF(AND(A25=INT(A25), LEN(A25)=3), 2, LEN(A25) - FIND(".", A25) + 2) ) ), "") | C25: Control building | D25: =REPT(" ", B25*2) & C25
A26: 213.21 | B26: =IF(ISNUMBER(A26), IF(AND(A26=INT(A26), MOD(A26, 10) = 0), 0, IF(AND(A26=INT(A26), LEN(A26)=2), 1, IF(AND(A26=INT(A26), LEN(A26)=3), 2, LEN(A26) - FIND(".", A26) + 2) ) ), "") | C26: Control Building Slab Roof | D26: =REPT(" ", B26*2) & C26 | E26: standard | K26: =1200 | L26: $/m^3 | M26: Control Building Slab Roof Volume | O26: m^3 | Q26: 2024 | R26: Lab and Mat and Equip | S26: RSMeans software: a tool that primarily provides costs for non-nuclear work | T26: GORDIAN. (2024). "RSMeans data. & Delene, J. G. and I. Hudson, C. R. (1993). Cost estimate guidelines for advanced nuclear power technologies. United States, Oak Ridge National Lab. (ORNL), Oak Ridge, TN (United States): Medium: ED; Size: 159 p. | U26: https://www.rsmeans.com/ & https://www.osti.gov/biblio/10176857 | W26: Onsite Learning | X26: =0.9*$J26 | Y26: =1.5*J26 | Z26: Lognormal | AA26: =0.9*K26 | AB26: =1.3*K26 | AC26: Lognormal | AD26: 0.1 | AE26: 1 | AF26: 0 | AG26: Truncated Normal
A27: 213.22 | B27: =IF(ISNUMBER(A27), IF(AND(A27=INT(A27), MOD(A27, 10) = 0), 0, IF(AND(A27=INT(A27), LEN(A27)=2), 1, IF(AND(A27=INT(A27), LEN(A27)=3), 2, LEN(A27) - FIND(".", A27) + 2) ) ), "") | C27: Control Building Basement | D27: =REPT(" ", B27*2) & C27 | E27: standard | K27: =943.9 | L27: $/m^3 | M27: Control Building Basement Volume | O27: m^3 | Q27: 2024 | R27: Lab and Mat and Equip | W27: Onsite Learning | X27: =0.9*$J27 | Y27: =1.5*J27 | Z27: Lognormal | AA27: =0.9*K27 | AB27: =1.3*K27 | AC27: Lognormal | AD27: 0.1 | AE27: 1 | AF27: 0 | AG27: Truncated Normal
A28: 213.23 | B28: =IF(ISNUMBER(A28), IF(AND(A28=INT(A28), MOD(A28, 10) = 0), 0, IF(AND(A28=INT(A28), LEN(A28)=2), 1, IF(AND(A28=INT(A28), LEN(A28)=3), 2, LEN(A28) - FIND(".", A28) + 2) ) ), "") | C28: Control Building Walls | D28: =REPT(" ", B28*2) & C28 | E28: standard | K28: =721.21 | L28: $/m^3 | M28: Control Building Exterior Walls Volume | O28: m^3 | Q28: 2024 | R28: Lab and Mat and Equip | W28: Onsite Learning | X28: =0.9*$J28 | Y28: =1.5*J28 | Z28: Lognormal | AA28: =0.9*K28 | AB28: =1.3*K28 | AC28: Lognormal | AD28: 0.1 | AE28: 1 | AF28: 0 | AG28: Truncated Normal
A29: 213.3 | B29: =IF(ISNUMBER(A29), IF(AND(A29=INT(A29), MOD(A29, 10) = 0), 0, IF(AND(A29=INT(A29), LEN(A29)=2), 1, IF(AND(A29=INT(A29), LEN(A29)=3), 2, LEN(A29) - FIND(".", A29) + 2) ) ), "") | C29: Integrated Heat Exchanger Building | D29: =REPT(" ", B29*2) & C29 | F29: reactor type | G29: GCMR
A30: 213.31 | B30: =IF(ISNUMBER(A30), IF(AND(A30=INT(A30), MOD(A30, 10) = 0), 0, IF(AND(A30=INT(A30), LEN(A30)=2), 1, IF(AND(A30=INT(A30), LEN(A30)=3), 2, LEN(A30) - FIND(".", A30) + 2) ) ), "") | C30: Integrated Heat Exchanger Building Slab Roof | D30: =REPT(" ", B30*2) & C30 | E30: standard | F30: reactor type | G30: GCMR | K30: =1200 | L30: $/m^3 | M30: Integrated Heat Exchanger Building Slab Roof Volume | O30: m^3 | Q30: 2024 | R30: Lab and Mat and Equip | S30: RSMeans software: a tool that primarily provides costs for non-nuclear work | T30: GORDIAN. (2024). "RSMeans data. & Delene, J. G. and I. Hudson, C. R. (1993). Cost estimate guidelines for advanced nuclear power technologies. United States, Oak Ridge National Lab. (ORNL), Oak Ridge, TN (United States): Medium: ED; Size: 159 p. | U30: https://www.rsmeans.com/ & https://www.osti.gov/biblio/10176857 | W30: Onsite Learning | X30: =0.9*$J30 | Y30: =1.5*J30 | Z30: Lognormal | AA30: =0.9*K30 | AB30: =1.3*K30 | AC30: Lognormal | AD30: 0.1 | AE30: 1 | AF30: 0 | AG30: Truncated Normal
A31: 213.32 | B31: =IF(ISNUMBER(A31), IF(AND(A31=INT(A31), MOD(A31, 10) = 0), 0, IF(AND(A31=INT(A31), LEN(A31)=2), 1, IF(AND(A31=INT(A31), LEN(A31)=3), 2, LEN(A31) - FIND(".", A31) + 2) ) ), "") | C31: Integrated Heat Exchanger Building Basement | D31: =REPT(" ", B31*2) & C31 | E31: standard | F31: reactor type | G31: GCMR | K31: =943.9 | L31: $/m^3 | M31: Integrated Heat Exchanger Building Basement Volume | O31: m^3 | Q31: 2024 | R31: Lab and Mat and Equip | W31: Onsite Learning | X31: =0.9*$J31 | Y31: =1.5*J31 | Z31: Lognormal | AA31: =0.9*K31 | AB31: =1.3*K31 | AC31: Lognormal | AD31: 0.1 | AE31: 1 | AF31: 0 | AG31: Truncated Normal
A32: 213.33 | B32: =IF(ISNUMBER(A32), IF(AND(A32=INT(A32), MOD(A32, 10) = 0), 0, IF(AND(A32=INT(A32), LEN(A32)=2), 1, IF(AND(A32=INT(A32), LEN(A32)=3), 2, LEN(A32) - FIND(".", A32) + 2) ) ), "") | C32: Integrated Heat Exchanger Building Walls | D32: =REPT(" ", B32*2) & C32 | E32: standard | F32: reactor type | G32: GCMR | K32: =721.21 | L32: $/m^3 | M32: Integrated Heat Exchanger Building Exterior Walls Volume | O32: m^3 | Q32: 2024 | R32: Lab and Mat and Equip | W32: Onsite Learning | X32: =0.9*$J32 | Y32: =1.5*J32 | Z32: Lognormal | AA32: =0.9*K32 | AB32: =1.3*K32 | AC32: Lognormal | AD32: 0.1 | AE32: 1 | AF32: 0 | AG32: Truncated Normal
A33: 213.34 | B33: =IF(ISNUMBER(A33), IF(AND(A33=INT(A33), MOD(A33, 10) = 0), 0, IF(AND(A33=INT(A33), LEN(A33)=2), 1, IF(AND(A33=INT(A33), LEN(A33)=3), 2, LEN(A33) - FIND(".", A33) + 2) ) ), "") | C33: Integrated Heat Exchanger Building Liner | D33: =REPT(" ", B33*2) & C33 | E33: standard | F33: reactor type | G33: GCMR | K33: =60848829/9373 | L33: $/m^2 | M33: Integrated Heat Exchanger Building Superstructure Area | N33: 9373 | O33: m^2 | P33: 1 | Q33: 2018 | R33: Lab and Mat and Equip | S33: Stewart W.R., Shirvan K., "Capital cost estimation for advanced nuclear power plants," Renewable and Sustainable Energy Reviews, Nov. 2021, 111880 | T33: Stewart W.R., Shirvan K., "Capital cost estimation for advanced nuclear power plants," Renewable and Sustainable Energy Reviews, Nov. 2021, 111880 | U33: https://doi.org/10.1016/j.rser.2021.111880 | W33: Onsite Learning | X33: =0.9*$J33 | Y33: =1.5*J33 | Z33: Lognormal | AA33: =0.9*K33 | AB33: =1.3*K33 | AC33: Lognormal | AD33: 0.1 | AE33: 1 | AF33: 0 | AG33: Truncated Normal
A34: 214 | B34: =IF(ISNUMBER(A34), IF(AND(A34=INT(A34), MOD(A34, 10) = 0), 0, IF(AND(A34=INT(A34), LEN(A34)=2), 1, IF(AND(A34=INT(A34), LEN(A34)=3), 2, LEN(A34) - FIND(".", A34) + 2) ) ), "") | C34: Buildings to Support Main Function | D34: =REPT(" ", B34*2) & C34
A35: 214.1 | B35: =IF(ISNUMBER(A35), IF(AND(A35=INT(A35), MOD(A35, 10) = 0), 0, IF(AND(A35=INT(A35), LEN(A35)=2), 1, IF(AND(A35=INT(A35), LEN(A35)=3), 2, LEN(A35) - FIND(".", A35) + 2) ) ), "") | C35: Fuel Management Buildings | D35: =REPT(" ", B35*2) & C35
A36: 214.11 | B36: =IF(ISNUMBER(A36), IF(AND(A36=INT(A36), MOD(A36, 10) = 0), 0, IF(AND(A36=INT(A36), LEN(A36)=2), 1, IF(AND(A36=INT(A36), LEN(A36)=3), 2, LEN(A36) - FIND(".", A36) + 2) ) ), "") | C36: Refueling Building | D36: =REPT(" ", B36*2) & C36
A37: 214.111 | B37: =IF(ISNUMBER(A37), IF(AND(A37=INT(A37), MOD(A37, 10) = 0), 0, IF(AND(A37=INT(A37), LEN(A37)=2), 1, IF(AND(A37=INT(A37), LEN(A37)=3), 2, LEN(A37) - FIND(".", A37) + 2) ) ), "") | C37: Refueling Building Slab Roof | D37: =REPT(" ", B37*2) & C37 | E37: standard | K37: =1200 *1.53 | L37: $/m^3 | M37: Refueling Building Slab Roof Volume | O37: m^3 | Q37: 2024 | R37: Lab and Mat and Equip | S37: RSMeans software: a tool that primarily provides costs for non-nuclear work Nuclear Multiplier have been applied to adjust the costs for nuclear-site-related work | T37: GORDIAN. (2024). "RSMeans data. & Delene, J. G. and I. Hudson, C. R. (1993). Cost estimate guidelines for advanced nuclear power technologies. United States, Oak Ridge National Lab. (ORNL), Oak Ridge, TN (United States): Medium: ED; Size: 159 p. | U37: https://www.rsmeans.com/ & https://www.osti.gov/biblio/10176857 | W37: Onsite Learning | X37: =0.9*$J37 | Y37: =1.5*J37 | AA37: =0.9*K37 | AB37: =1.3*K37 | AC37: Lognormal | AD37: 0.1 | AE37: 1 | AF37: 0 | AG37: Truncated Normal
A38: 214.112 | B38: =IF(ISNUMBER(A38), IF(AND(A38=INT(A38), MOD(A38, 10) = 0), 0, IF(AND(A38=INT(A38), LEN(A38)=2), 1, IF(AND(A38=INT(A38), LEN(A38)=3), 2, LEN(A38) - FIND(".", A38) + 2) ) ), "") | C38: Refueling Building Basement | D38: =REPT(" ", B38*2) & C38 | E38: standard | K38: =943.9*1.53 | L38: $/m^3 | M38: Refueling Building Basement Volume | O38: m^3 | Q38: 2024 | R38: Lab and Mat and Equip | W38: Onsite Learning | X38: =0.9*$J38 | Y38: =1.5*J38 | Z38: Lognormal | AA38: =0.9*K38 | AB38: =1.3*K38 | AC38: Lognormal | AD38: 0.1 | AE38: 1 | AF38: 0 | AG38: Truncated Normal
A39: 214.113 | B39: =IF(ISNUMBER(A39), IF(AND(A39=INT(A39), MOD(A39, 10) = 0), 0, IF(AND(A39=INT(A39), LEN(A39)=2), 1, IF(AND(A39=INT(A39), LEN(A39)=3), 2, LEN(A39) - FIND(".", A39) + 2) ) ), "") | C39: Refueling Building Walls | D39: =REPT(" ", B39*2) & C39 | E39: standard | K39: =721.21*1.53 | L39: $/m^3 | M39: Refueling Building Exterior Walls Volume | O39: m^3 | Q39: 2024 | R39: Lab and Mat and Equip | W39: Onsite Learning | X39: =0.9*$J39 | Y39: =1.5*J39 | Z39: Lognormal | AA39: =0.9*K39 | AB39: =1.3*K39 | AC39: Lognormal | AD39: 0.1 | AE39: 1 | AF39: 0 | AG39: Truncated Normal
A40: 214.12 | B40: =IF(ISNUMBER(A40), IF(AND(A40=INT(A40), MOD(A40, 10) = 0), 0, IF(AND(A40=INT(A40), LEN(A40)=2), 1, IF(AND(A40=INT(A40), LEN(A40)=3), 2, LEN(A40) - FIND(".", A40) + 2) ) ), "") | C40: Spent Fuel Building | D40: =REPT(" ", B40*2) & C40
...

Sheet MARVEL_Cost
A1: Account ID | B1: Account Title | C1: TOTAL COST (2024 USD)
A3: 10 | B3: Capitalized Pre-Construction Costs | C3: =C4
A4: 15 | B4: Plant Studies | C4: 5210451
A5: 20 | B5: Capitalized Direct Costs | C5: =C6+C13+C45+C48+C52+C54
A6: 21 | B6: Structures and Improvements | C6: =C7+C8+C9+C10
A7: 211 | B7: Site Preparation/Yard Work
A8: 212 | B8: Reactor Island Civil Structures | C8: 2573469.9
A9: 213 | B9: Main Function Buildings
A10: 214 | B10: Buildings to Support Main Function | C10: =SUM(C11:C11)
A11: 214.7 | B11: Emergency and Start-up Power Systems | C11: 225536.86
A12: 217 | B12: Miscellaneous Other Structures
A13: 22 | B13: Reactor System | C13: =C14+C32+C41+C42+C43+C44
A14: 221 | B14: Reactor Components | C14: =C15+C19+C25
A15: 221.1 | B15: Reactor vessel and accessories | C15: =C16+C17+C18
A16: 221.11 | B16: Reactor support | C16: 762382.4
A17: 221.12 | B17: Outer vessel structure | C17: 1201688.6
A18: 221.13 | B18: Inner vessel structure | C18: 40781
A19: 221.2 | B19: Reactor control devices | C19: =C20
A20: 221.21 | B20: Reactivity control system | C20: =SUM(C21:C23)
A21: 221.211 | B21: Reactivity Control System Fabrication | C21: 1391560
A22: 221.212 | B22: Installation | C22: 322663
A23: 221.213 | B23: Control Drums Materials (Absorber) | C23: 400000
A24: 221.214 | B24: Control Drums Materials (Reflector)
A25: 221.3 | B25: Non-fuel core internals | C25: =C26+C30+C31
A26: 221.31 | B26: Reflector | C26: 4170231
A27: 221.311 | B27: Reflector (Materials: BeO) | C27: 3200000
A28: 221.312 | B28: Reflector (Materials: Be Metal) | C28: 850000
A29: 221.313 | B29: Reflector (installation | C29: 120231
A30: 221.32 | B30: Shield | C30: 647990.6
A31: 221.33 | B31: Moderator | C31: 0
A32: 222 | B32: Main Heat Transport System | C32: =C33+C34+C38+C39+C40
A33: 222.1 | B33: Fluid circulation drive system | C33: 0
A34: 222.2 | B34: Reactor Heat Hransfer Piping System | C34: 4890230.6
A35: 222.21 | B35: Reactor Heat Hransfer Piping System (Mat) | C35: 1520786
A36: 222.22 | B36: Reactor Heat Hransfer Piping System (Fabrication) | C36: 3341486
A37: 222.23 | B37: Reactor Heat Hransfer Piping System (Installation) | C37: 27958.6
A38: 222.3 | B38: Heat Exchangers | C38: 0
A39: 222.4 | B39: Pressurizer System | C39: 0
A40: 222.5 | B40: Initial Heat Transfer Fluid Inventory | C40: 1018720
A41: 224 | B41: Radioactive Byproduct Processing Systems
...

Sheet Design Variables
A1: Variable | B1: Value | C1: Units | D1: Description
A2: Overall System
A3: Thermal power | B3: 83 | C3: kWth | D3: —
A4: Electric Power | B4: 20 | C4: kWe
A5: Core outer radius | B5: 5.5 | C5: inches | D5: —
A6: Reflector outer radius | B6: 16.5 | C6: inches | D6: —
A7: Fuel
A8: Fuel mass | B8: 145.3 | C8: kg | D8: UZrH
A9: U Weight fraction | B9: 30 | C9: wt% | D9: U/UZrH
A10: U enrichment | B10: 19.75 | C10: wt% | D10: High-assay low-enriched uranium (HALEU)
A11: Pins | B11: 36 | C11: # | D11: —
A12: Reflector
A13: Outer reflector material | B13: BeO | C13: — | D13: 99% theoretical density
A14: Elements | B14: 124 | C14: # | D14: Quarter plates
A15: Reflector plate thickness | B15: 1 | C15: inches | D15: —
A16: Reflector plate volume | B16: 818.4 | C16: cm3/plate | D16: —
A17: Mass of BeO reflector | B17: 318 | C17: Kg
A18: Insert volume | B18: 570 | C18: cm3/plate | D18: —
A19: Mass of Be-metal reflector | B19: 0.019 | C19: MT | D19: —
A20: Control Elements
A21: Control drums | B21: 4 | C21: # | D21: —
A22: Shutdown rods | B22: 1 | C22: # | D22: —
A23: Control drum elements | B23: 124 | C23: # | D23: Discs
A24: Drum disc thickness | B24: 1 | C24: inches | D24: —
A25: Drum reflector volume | B25: 880.8 | C25: cm3/plate | D25: BeO 99%
A26: Mass of drum reflector | B26: 309 | C26: Kg | D26: —
A27: Drum poison volume | B27: 49.2 | C27: cm3/plate | D27: B4C
A28: Mass of drum poison | B28: 14 | C28: Kg | D28: —
A29: Mass of rod poison | B29: 14 | C29: Kg | D29: B4C
A30: Instruments and Controls
A31: Control cabinet | B31: 5 | D31: —
A32: Instrument cabinet | B32: 2 | D32: —
A33: Nuclear input/output (IO) | B33: 9 | D33: —
A34: Non-nuclear IO | B34: 213 | D34: —
A35: Stirling engine IO | B35: 48 | C35: — | D35: These should be excluded if there no stirling engine?
A36: TOTAL | B36: 277
A37: Shielding in Vessel
A38: Stainless Steel cans | B38: 54.2 | C38: Kg | D38: Stainless Steel cans of the boron carbide shielding material (SS316H)
A39: Gamma shield material | B39: 56.3 | C39: Kg | D39: Gamma shield material inside the guard vessel (of Tungsten)
A40: Neutron shield material in the guard vessel | B40: 39.7 | C40: Kg | D40: made of natural B4C powder and is located above the core (a donut around the core barrel)—
...

Sheet Inflation Adjustment
A1: Year | B1: General | C1: Labor | D1: Material | E1: Equipment | F1: Lab and Mat and Equip | G1: Lab and Equip
A2: 1978 | B2: 3.1209 | C2: 4.2536 | D2: 3.811 | E2: 5.3954 | F2: =(C2+D2+E2)/3 | G2: =AVERAGE(C2,E2)
A3: 1985 | B3: 2.53801 | C3: 3.3122863 | D3: 3.1461261 | E3: 4.0603969 | F3: =(C3+D3+E3)/3 | G3: =AVERAGE(C3,E3)
A4: 1986 | B4: 2.4877976 | C4: 3.2086278 | D4: 3.1524765 | E4: 3.957082 | F4: =(C4+D4+E4)/3 | G4: =AVERAGE(C4,E4)
A5: 1987 | B5: 2.4278243 | C5: 3.1112605 | D5: 3.0891631 | E5: 3.9210211 | F5: =(C5+D5+E5)/3 | G5: =AVERAGE(C5,E5)
A6: 1988 | B6: 2.3451469 | C6: 2.989825 | D6: 2.9257907 | E6: 3.7360352 | F6: =(C6+D6+E6)/3 | G6: =AVERAGE(C6,E6)
A7: 1989 | B7: 2.2565183 | C7: 2.8925 | D7: 2.8323254 | E7: 3.5114259 | F7: =(C7+D7+E7)/3 | G7: =AVERAGE(C7,E7)
A8: 1990 | B8: 2.1749312 | C8: 2.765278 | D8: 2.828971 | E8: 3.4175276 | F8: =(C8+D8+E8)/3 | G8: =AVERAGE(C8,E8)
A9: 1991 | B9: 2.103917 | C9: 2.6561658 | D9: 2.8109546 | E9: 3.3052946 | F9: =(C9+D9+E9)/3 | G9: =AVERAGE(C9,E9)
A10: 1992 | B10: 2.0570925 | C10: 2.5740904 | D10: 2.7621964 | E10: 3.1693577 | F10: =(C10+D10+E10)/3 | G10: =AVERAGE(C10,E10)
A11: 1993 | B11: 2.0094227 | C11: 2.4922663 | D11: 2.6313537 | E11: 2.9935069 | F11: =(C11+D11+E11)/3 | G11: =AVERAGE(C11,E11)
A12: 1994 | B12: 1.967432 | C12: 2.4032889 | D12: 2.528144 | E12: 2.9062257 | F12: =(C12+D12+E12)/3 | G12: =AVERAGE(C12,E12)
A13: 1995 | B13: 1.9269732 | C13: 2.3615592 | D13: 2.4372516 | E13: 2.8565425 | F13: =(C13+D13+E13)/3 | G13: =AVERAGE(C13,E13)
... A43: 2025 | B43: 1 | C43: 1 | D43: 1 | E43: 1 | F43: =(C43+D43+E43)/3 | G43: =AVERAGE(C43,E43)

Sheet Economics Parameters
A1: Parameter | B1: Value | C1: Note | D1: Reference | E1: Notes
A2: indirect to direct field-related cost | B2: 0.065389932
A3: FTEs Per Onsite Operator (24/7) | B3: 5
A4: FTEs Per Offsite Operator (24/7) | B4: 5
A5: FTEs Per Security Staff (24/7) | B5: 5
A6: Hours Per FTE | B6: 1800
A7: Work Hours Per Shift | B7: 10
A8: Maintenance to Direct Cost Ratio | B8: 0.03
A9: Onsite Learning | B9: 0.08 | C9: FOAK to NOAK Learning Rates | D9: Assessment of Factory Fabrication Considerations for Nuclear Microreactors 10.1080/00295450.2023.2206779 | E9: Calculated based on Refernce Paper + Gyutae's work. Refer to TEM Slides for rationale and methodology
A10: No Learning | B10: 0
A11: Licensing Learning | B11: 0
A12: Factory Primary Structure | B12: 0.1844317
A13: Factory Drums | B13: 0.24138
A14: Factory Other | B14: 0.22962848
A15: Factory Be | B15: 0.41505378
A16: Factory BeO | B16: 0.39914906
A17: Non-nuclear off-the-shelf | B17: 0.05 | D17: Park, et al., Bottom-up levelized cost estimation of low-enriched and low-pressure nuclear batteries. Nuclear Engineering and Design. 2025. | E17: For off-the-shelf commercial components that are not produced in the FB Factory

Sheet Central Facility Database
A1: Account | B1: Level | C1: Account Name | D1: Account Title | E1: Standard Cost Equation? | F1: Count Scaling Variable | G1: Count per Variable | H1: Optional Variable | I1: Optional Value | J1: Fixed Cost ($) | K1: Unit Cost | L1: Unit Cost (units) | M1: Scaling Variable | N1: Scaling Variable Ref Value | O1: Units | P1: Exponent | Q1: Dollar Year | R1: Type | S1: Source | T1: Ref | U1: Link | V1: Notes | W1: FOAK to NOAK Multiplier Type | X1: Fixed Cost Low End | Y1: Fixed Cost High End | Z1: Fixed Cost Distribution | AA1: Unit Cost Low End | AB1: Unit Cost High End | AC1: Unit Cost Distribution | AD1: Exponent std | AE1: Exponent Max | AF1: Exponent Min | AG1: Exponent Distribution
A2: 10 | B2: 0 | C2: Capitalized Pre-Construction Costs | D2: =REPT(" ", B2*2) & C2
A3: 11 | B3: 1 | C3: Land Cost | D3: =REPT(" ", B3*2) & C3 | E3: standard | F3: Constant | G3: 1 | K3: 3800 | L3: $/acres | M3: Land Area | O3: acres | Q3: 2022 | R3: General | S3: The average cost per acre for rural land in 2022 from the US Department of Agriculture | T3: Abou-Jaoude, A., Lohse, C. S., Larsen, L. M., Guaita, N., Trivedi, I., Joseck, F. C., ... & Stein, A. (2024). Meta-analysis of advanced nuclear reactor cost estimations (No. INL/RPT-24-77048-Rev001). Idaho National Laboratory (INL), Idaho Falls, ID (United States). | U3: https://inldigitallibrary.inl.gov/sites/sti/sti/Sort_107010.pdf | W3: No Learning | X3: =0.9*$J3 | Y3: =1.5*J3 | Z3: Lognormal | AA3: =0.9*K3 | AB3: =1.3*K3 | AC3: Lognormal | AD3: 0.1 | AE3: 1 | AF3: 0 | AG3: Truncated Normal
A4: 12 | B4: 1 | C4: Site Permits | D4: =REPT(" ", B4*2) & C4 | E4: standard | F4: Constant | G4: 1 | K4: =10.03*1000 | L4: $/MWe | M4: Power MWe | O4: MWe | Q4: 2022 | R4: Labor | S4: Data from SMR MHTGRs | W4: No Learning | X4: =0.9*$J4 | Y4: =1.5*J4 | Z4: Lognormal | AA4: =0.9*K4 | AB4: =1.3*K4 | AC4: Lognormal | AD4: 0.1 | AE4: 1 | AF4: 0 | AG4: Truncated Normal
A5: 13 | B5: 1 | C5: Plant Licensing | D5: =REPT(" ", B5*2) & C5 | E5: standard | F5: Constant | G5: 1 | J5: =1000000*(45+70)/2 | Q5: 2009 | R5: Labor | S5: NGNP project | T5: Gandrik, A., B. Wallace, L. Demick, S. Melancon and M. Patterson (2011). "Assessment of high temperature gas-cooled reactor (HTGR) capital and operating costs." Idaho National Laboratory, TEV-1196, Idaho Falls, ID. | U5: https://art.inl.gov/NGNP/INL%20Documents/Year%202012/Assessment%20of%20High%20Temperature%20Gas-Cooled%20Reactor%20-%20HTGR%20-%20Capital%20and%20Operating%20Costs.pdf | W5: No Learning | X5: =45*1000000 | Y5: =70*1000000 | Z5: Uniform | AA5: =0.9*K5 | AB5: =1.3*K5 | AC5: Lognormal | AD5: 0.1 | AE5: 1 | AF5: 0 | AG5: Truncated Normal
A6: 14 | B6: 1 | C6: Plant Permits | D6: =REPT(" ", B6*2) & C6 | E6: standard | F6: Constant | G6: 1 | J6: 3000000 | Q6: 2009 | R6: Labor | S6: NGNP project | W6: No Learning | X6: =0.9*$J6 | Y6: =1.5*J6 | Z6: Lognormal | AA6: =0.9*K6 | AB6: =1.3*K6 | AC6: Lognormal | AD6: 0.1 | AE6: 1 | AF6: 0 | AG6: Truncated Normal
A7: 15 | B7: 1 | C7: Plant Studies | D7: =REPT(" ", B7*2) & C7 | E7: standard | F7: Constant | G7: 1 | J7: =MARVEL_Cost!C4 | Q7: 2024 | R7: Labor | S7: MARVEL Project (Labor-adjusted Cost) | T7: Hanna, B. N., Gonzaga de Oliveira, R. G., Mohammad Al Dawood, K. A., Patterson, M. D., Abou Jaoude, A., & Garcia, S. (2024). Technoeconomic Evaluation of Microreactor Using Detailed Bottom-up Estimate (No. INL/RPT-24-80433-Rev000). Idaho National Laboratory (INL), Idaho Falls, ID (United States). | U7: https://inldigitallibrary.inl.gov/sites/sti/sti/Sort_129862.pdf | V7: MARVEL's data were updated | W7: No Learning | X7: =0.9*$J7 | Y7: =1.5*J7 | Z7: Lognormal | AA7: =0.9*K7 | AB7: =1.3*K7 | AC7: Lognormal | AD7: 0.1 | AE7: 1 | AF7: 0 | AG7: Truncated Normal
A8: 20 | B8: 0 | C8: Capitalized Direct Costs | D8: =REPT(" ", B8*2) & C8
A9: 21 | B9: 1 | C9: Structures and Improvements | D9: =REPT(" ", B9*2) & C9
A10: 211 | B10: 2 | C10: Site Preparation/ Yard Work | D10: =REPT(" ", B10*2) & C10
A11: 211.1 | B11: 3 | C11: Cleaning and Grubbing | D11: =REPT(" ", B11*2) & C11 | E11: standard | F11: Constant | G11: 1 | K11: =4408.18*1.33 | L11: $/acres | M11: Land Area | O11: acres | Q11: 2024 | R11: Lab and Equip | S11: RSMeans software: a tool that primarily provides costs for non-nuclear work Nuclear Multiplier have been applied to adjust the costs for nuclear-site-related work | T11: GORDIAN. (2024). "RSMeans data. & Delene, J. G. and I. Hudson, C. R. (1993). Cost estimate guidelines for advanced nuclear power technologies. United States, Oak Ridge National Lab. (ORNL), Oak Ridge, TN (United States): Medium: ED; Size: 159 p. | U11: https://www.rsmeans.com/ & https://www.osti.gov/biblio/10176857 | W11: No Learning | X11: =0.9*$J11 | Y11: =1.5*J11 | Z11: Lognormal | AA11: =0.9*K11 | AB11: =1.3*K11 | AC11: Lognormal | AD11: 0.1 | AE11: 1 | AF11: 0 | AG11: Truncated Normal
A12: 211.2 | B12: 3 | C12: Stripping Topsoil | D12: =REPT(" ", B12*2) & C12 | E12: standard | F12: Constant | G12: 1 | K12: =2565.2*1.33 | L12: $/acres | M12: Land Area | O12: acres | Q12: 2024 | R12: Lab and Equip | W12: No Learning | X12: =0.9*$J12 | Y12: =1.5*J12 | Z12: Lognormal | AA12: =0.9*K12 | AB12: =1.3*K12 | AC12: Lognormal | AD12: 0.1 | AE12: 1 | AF12: 0 | AG12: Truncated Normal
A13: 211.3 | B13: 3 | C13: Excavation | D13: =REPT(" ", B13*2) & C13 | E13: standard | F13: Constant | G13: 1 | K13: =22.86*1.4 | L13: $/m^3 | M13: Excavation Volume | O13: m^3 | Q13: 2024 | R13: Lab and Equip | W13: No Learning | X13: =0.9*$J13 | Y13: =1.5*J13 | Z13: Lognormal | AA13: =0.9*K13 | AB13: =1.3*K13 | AC13: Lognormal | AD13: 0.1 | AE13: 1 | AF13: 0 | AG13: Truncated Normal
A14: 211.4 | B14: =IF(ISNUMBER(A14), IF(AND(A14=INT(A14), MOD(A14, 10) = 0), 0, IF(AND(A14=INT(A14), LEN(A14)=2), 1, IF(AND(A14=INT(A14), LEN(A14)=3), 2, LEN(A14) - FIND(".", A14) + 2) ) ), "") | C14: Roadwork | D14: =REPT(" ", B14*2) & C14 | E14: standard | F14: Constant | G14: 1 | W14: No Learning | X14: =0.9*$J14 | Y14: =1.5*J14 | Z14: Lognormal | AA14: =0.9*K14 | AB14: =1.3*K14 | AC14: Lognormal | AD14: 0.1 | AE14: 1 | AF14: 0 | AG14: Truncated Normal
A15: 211.9 | B15: =IF(ISNUMBER(A15), IF(AND(A15=INT(A15), MOD(A15, 10) = 0), 0, IF(AND(A15=INT(A15), LEN(A15)=2), 1, IF(AND(A15=INT(A15), LEN(A15)=3), 2, LEN(A15) - FIND(".", A15) + 2) ) ), "") | C15: Security Fencing | D15: =REPT(" ", B15*2) & C15 | E15: standard | F15: Constant | G15: 1 | K15: =75/0.3048 | L15: $/m | M15: Site Perimeter | Q15: 2009 | R15: Lab and Equip | S15: Ref Table 2-8 | T15: Kessler. Cost Estimate for an Away-From-Reactor Generic Interim Storage Facility (GISF) for Spent Nuclear Fuel. EPRI. 2009. | U15: https://www.epri.com/research/products/1018722 | W15: No Learning | X15: =0.9*$J15 | Y15: =1.5*J15 | Z15: Lognormal | AA15: =0.9*K15 | AB15: =1.3*K15 | AC15: Lognormal | AD15: 0.1 | AE15: 1 | AF15: 0 | AG15: Truncated Normal
A16: 213 | B16: =IF(ISNUMBER(A16), IF(AND(A16=INT(A16), MOD(A16, 10) = 0), 0, IF(AND(A16=INT(A16), LEN(A16)=2), 1, IF(AND(A16=INT(A16), LEN(A16)=3), 2, LEN(A16) - FIND(".", A16) + 2) ) ), "") | C16: Manufacturing Facility | D16: =REPT(" ", B16*2) & C16
A17: 213.1 | B17: =IF(ISNUMBER(A17), IF(AND(A17=INT(A17), MOD(A17, 10) = 0), 0, IF(AND(A17=INT(A17), LEN(A17)=2), 1, IF(AND(A17=INT(A17), LEN(A17)=3), 2, LEN(A17) - FIND(".", A17) + 2) ) ), "") | C17: Fabrication Building | D17: =REPT(" ", B17*2) & C17
A18: 213.11 | B18: =IF(ISNUMBER(A18), IF(AND(A18=INT(A18), MOD(A18, 10) = 0), 0, IF(AND(A18=INT(A18), LEN(A18)=2), 1, IF(AND(A18=INT(A18), LEN(A18)=3), 2, LEN(A18) - FIND(".", A18) + 2) ) ), "") | C18: =_xlfn.CONCAT(C17," Roof") | D18: =REPT(" ", B18*2) & C18 | E18: standard | F18: Constant | G18: 1 | K18: =1200 | L18: $/m^3 | M18: =_xlfn.CONCAT(C18, " Volume") | O18: m^3 | Q18: 2024 | R18: Lab and Mat and Equip | S18: RSMeans software: a tool that primarily provides costs for non-nuclear work Nuclear Multiplier have not been applied | T18: GORDIAN. (2024). "RSMeans data. & Delene, J. G. and I. Hudson, C. R. (1993). Cost estimate guidelines for advanced nuclear power technologies. United States, Oak Ridge National Lab. (ORNL), Oak Ridge, TN (United States): Medium: ED; Size: 159 p. | U18: https://www.rsmeans.com/ & https://www.osti.gov/biblio/10176857 | W18: No Learning | X18: =0.9*$I18 | Y18: =1.5*J18 | Z18: Lognormal | AA18: =0.9*K18 | AB18: =1.3*K18 | AC18: Lognormal | AD18: 0.1 | AE18: 1 | AF18: 0 | AG18: Truncated Normal
A19: 213.12 | B19: =IF(ISNUMBER(A19), IF(AND(A19=INT(A19), MOD(A19, 10) = 0), 0, IF(AND(A19=INT(A19), LEN(A19)=2), 1, IF(AND(A19=INT(A19), LEN(A19)=3), 2, LEN(A19) - FIND(".", A19) + 2) ) ), "") | C19: =_xlfn.CONCAT(C17," Basement") | D19: =REPT(" ", B19*2) & C19 | E19: standard | F19: Constant | G19: 1 | K19: =943.9 | L19: $/m^3 | M19: =_xlfn.CONCAT(C19, " Volume") | O19: m^3 | Q19: 2024 | R19: Lab and Mat and Equip | W19: No Learning | X19: =0.9*$I19 | Y19: =1.5*J19 | Z19: Lognormal | AA19: =0.9*K19 | AB19: =1.3*K19 | AC19: Lognormal | AD19: 0.1 | AE19: 1 | AF19: 0 | AG19: Truncated Normal
A20: 213.13 | B20: =IF(ISNUMBER(A20), IF(AND(A20=INT(A20), MOD(A20, 10) = 0), 0, IF(AND(A20=INT(A20), LEN(A20)=2), 1, IF(AND(A20=INT(A20), LEN(A20)=3), 2, LEN(A20) - FIND(".", A20) + 2) ) ), "") | C20: =_xlfn.CONCAT(C17," Walls") | D20: =REPT(" ", B20*2) & C20 | E20: standard | F20: Constant | G20: 1 | K20: =721.21 | L20: $/m^3 | M20: =_xlfn.CONCAT(C20, " Volume") | O20: m^3 | Q20: 2024 | R20: Lab and Mat and Equip | W20: No Learning | X20: =0.9*$I20 | Y20: =1.5*J20 | Z20: Lognormal | AA20: =0.9*K20 | AB20: =1.3*K20 | AC20: Lognormal | AD20: 0.1 | AE20: 1 | AF20: 0 | AG20: Truncated Normal
A21: 213.19 | B21: =IF(ISNUMBER(A21), IF(AND(A21=INT(A21), MOD(A21, 10) = 0), 0, IF(AND(A21=INT(A21), LEN(A21)=2), 1, IF(AND(A21=INT(A21), LEN(A21)=3), 2, LEN(A21) - FIND(".", A21) + 2) ) ), "") | C21: HVAC | D21: =REPT(" ", B21*2) & C21 | E21: standard | F21: Constant | G21: 1 | L21: $/m^3 | M21: =_xlfn.CONCAT(C17, " Volume") | O21: m^3 | W21: No Learning | X21: =0.9*$I21 | Y21: =1.5*J21 | Z21: Lognormal | AA21: =0.9*K21 | AB21: =1.3*K21 | AC21: Lognormal | AD21: 0.1 | AE21: 1 | AF21: 0 | AG21: Truncated Normal
A22: 213.2 | B22: =IF(ISNUMBER(A22), IF(AND(A22=INT(A22), MOD(A22, 10) = 0), 0, IF(AND(A22=INT(A22), LEN(A22)=2), 1, IF(AND(A22=INT(A22), LEN(A22)=3), 2, LEN(A22) - FIND(".", A22) + 2) ) ), "") | C22: Feed and Product Warehouse Building | D22: =REPT(" ", B22*2) & C22
A23: 213.21 | B23: =IF(ISNUMBER(A23), IF(AND(A23=INT(A23), MOD(A23, 10) = 0), 0, IF(AND(A23=INT(A23), LEN(A23)=2), 1, IF(AND(A23=INT(A23), LEN(A23)=3), 2, LEN(A23) - FIND(".", A23) + 2) ) ), "") | C23: =_xlfn.CONCAT(C22," Roof") | D23: =REPT(" ", B23*2) & C23 | E23: standard | F23: Constant | G23: 1 | K23: =1200 | L23: $/m^3 | M23: =_xlfn.CONCAT(C23, " Volume") | O23: m^3 | Q23: 2024 | R23: Lab and Mat and Equip | S23: RSMeans software: a tool that primarily provides costs for non-nuclear work Nuclear Multiplier have not been applied | T23: GORDIAN. (2024). "RSMeans data. & Delene, J. G. and I. Hudson, C. R. (1993). Cost estimate guidelines for advanced nuclear power technologies. United States, Oak Ridge National Lab. (ORNL), Oak Ridge, TN (United States): Medium: ED; Size: 159 p. | U23: https://www.rsmeans.com/ & https://www.osti.gov/biblio/10176857 | W23: No Learning | X23: =0.9*$I23 | Y23: =1.5*J23 | Z23: Lognormal | AA23: =0.9*K23 | AB23: =1.3*K23 | AC23: Lognormal | AD23: 0.1 | AE23: 1 | AF23: 0 | AG23: Truncated Normal
A24: 213.22 | B24: =IF(ISNUMBER(A24), IF(AND(A24=INT(A24), MOD(A24, 10) = 0), 0, IF(AND(A24=INT(A24), LEN(A24)=2), 1, IF(AND(A24=INT(A24), LEN(A24)=3), 2, LEN(A24) - FIND(".", A24) + 2) ) ), "") | C24: =_xlfn.CONCAT(C22," Basement") | D24: =REPT(" ", B24*2) & C24 | E24: standard | F24: Constant | G24: 1 | K24: =943.9 | L24: $/m^3 | M24: =_xlfn.CONCAT(C24, " Volume") | O24: m^3 | Q24: 2024 | R24: Lab and Mat and Equip | W24: No Learning | X24: =0.9*$I24 | Y24: =1.5*J24 | Z24: Lognormal | AA24: =0.9*K24 | AB24: =1.3*K24 | AC24: Lognormal | AD24: 0.1 | AE24: 1 | AF24: 0 | AG24: Truncated Normal
A25: 213.23 | B25: =IF(ISNUMBER(A25), IF(AND(A25=INT(A25), MOD(A25, 10) = 0), 0, IF(AND(A25=INT(A25), LEN(A25)=2), 1, IF(AND(A25=INT(A25), LEN(A25)=3), 2, LEN(A25) - FIND(".", A25) + 2) ) ), "") | C25: =_xlfn.CONCAT(C22," Walls") | D25: =REPT(" ", B25*2) & C25 | E25: standard | F25: Constant | G25: 1 | K25: =721.21 | L25: $/m^3 | M25: =_xlfn.CONCAT(C25, " Volume") | O25: m^3 | Q25: 2024 | R25: Lab and Mat and Equip | W25: No Learning | X25: =0.9*$I25 | Y25: =1.5*J25 | Z25: Lognormal | AA25: =0.9*K25 | AB25: =1.3*K25 | AC25: Lognormal | AD25: 0.1 | AE25: 1 | AF25: 0 | AG25: Truncated Normal
A26: 213.29 | B26: =IF(ISNUMBER(A26), IF(AND(A26=INT(A26), MOD(A26, 10) = 0), 0, IF(AND(A26=INT(A26), LEN(A26)=2), 1, IF(AND(A26=INT(A26), LEN(A26)=3), 2, LEN(A26) - FIND(".", A26) + 2) ) ), "") | C26: HVAC | D26: =REPT(" ", B26*2) & C26 | E26: standard | F26: Constant | G26: 1 | L26: $/m^3 | M26: =_xlfn.CONCAT(C22, " Volume") | O26: m^3 | W26: No Learning | X26: =0.9*$I26 | Y26: =1.5*J26 | Z26: Lognormal | AA26: =0.9*K26 | AB26: =1.3*K26 | AC26: Lognormal | AD26: 0.1 | AE26: 1 | AF26: 0 | AG26: Truncated Normal
A27: 213.6 | B27: =IF(ISNUMBER(A27), IF(AND(A27=INT(A27), MOD(A27, 10) = 0), 0, IF(AND(A27=INT(A27), LEN(A27)=2), 1, IF(AND(A27=INT(A27), LEN(A27)=3), 2, LEN(A27) - FIND(".", A27) + 2) ) ), "") | C27: Manufacturing Facility Integrated Control Building | D27: =REPT(" ", B27*2) & C27
A28: 213.61 | B28: =IF(ISNUMBER(A28), IF(AND(A28=INT(A28), MOD(A28, 10) = 0), 0, IF(AND(A28=INT(A28), LEN(A28)=2), 1, IF(AND(A28=INT(A28), LEN(A28)=3), 2, LEN(A28) - FIND(".", A28) + 2) ) ), "") | C28: =_xlfn.CONCAT(C27," Roof") | D28: =REPT(" ", B28*2) & C28 | E28: standard | F28: Constant | G28: 1 | K28: =1200 | L28: $/m^3 | M28: =_xlfn.CONCAT(C28, " Volume") | O28: m^3 | Q28: 2024 | R28: Lab and Mat and Equip | S28: RSMeans software: a tool that primarily provides costs for non-nuclear work Nuclear Multiplier have not been applied | T28: GORDIAN. (2024). "RSMeans data. & Delene, J. G. and I. Hudson, C. R. (1993). Cost estimate guidelines for advanced nuclear power technologies. United States, Oak Ridge National Lab. (ORNL), Oak Ridge, TN (United States): Medium: ED; Size: 159 p. | U28: https://www.rsmeans.com/ & https://www.osti.gov/biblio/10176857 | W28: No Learning | X28: =0.9*$I28 | Y28: =1.5*J28 | Z28: Lognormal | AA28: =0.9*K28 | AB28: =1.3*K28 | AC28: Lognormal | AD28: 0.1 | AE28: 1 | AF28: 0 | AG28: Truncated Normal
A29: 213.62 | B29: =IF(ISNUMBER(A29), IF(AND(A29=INT(A29), MOD(A29, 10) = 0), 0, IF(AND(A29=INT(A29), LEN(A29)=2), 1, IF(AND(A29=INT(A29), LEN(A29)=3), 2, LEN(A29) - FIND(".", A29) + 2) ) ), "") | C29: =_xlfn.CONCAT(C27," Basement") | D29: =REPT(" ", B29*2) & C29 | E29: standard | F29: Constant | G29: 1 | K29: =943.9 | L29: $/m^3 | M29: =_xlfn.CONCAT(C29, " Volume") | O29: m^3 | Q29: 2024 | R29: Lab and Mat and Equip | W29: No Learning | X29: =0.9*$I29 | Y29: =1.5*J29 | Z29: Lognormal | AA29: =0.9*K29 | AB29: =1.3*K29 | AC29: Lognormal | AD29: 0.1 | AE29: 1 | AF29: 0 | AG29: Truncated Normal
A30: 213.63 | B30: =IF(ISNUMBER(A30), IF(AND(A30=INT(A30), MOD(A30, 10) = 0), 0, IF(AND(A30=INT(A30), LEN(A30)=2), 1, IF(AND(A30=INT(A30), LEN(A30)=3), 2, LEN(A30) - FIND(".", A30) + 2) ) ), "") | C30: =_xlfn.CONCAT(C27," Walls") | D30: =REPT(" ", B30*2) & C30 | E30: standard | F30: Constant | G30: 1 | K30: =721.21 | L30: $/m^3 | M30: =_xlfn.CONCAT(C30, " Volume") | O30: m^3 | Q30: 2024 | R30: Lab and Mat and Equip | W30: No Learning | X30: =0.9*$I30 | Y30: =1.5*J30 | Z30: Lognormal | AA30: =0.9*K30 | AB30: =1.3*K30 | AC30: Lognormal | AD30: 0.1 | AE30: 1 | AF30: 0 | AG30: Truncated Normal
A31: 213.69 | B31: =IF(ISNUMBER(A31), IF(AND(A31=INT(A31), MOD(A31, 10) = 0), 0, IF(AND(A31=INT(A31), LEN(A31)=2), 1, IF(AND(A31=INT(A31), LEN(A31)=3), 2, LEN(A31) - FIND(".", A31) + 2) ) ), "") | C31: HVAC | D31: =REPT(" ", B31*2) & C31 | E31: standard | F31: Constant | G31: 1 | L31: $/m^3 | M31: =_xlfn.CONCAT(C27, " Volume") | O31: m^3 | W31: No Learning | X31: =0.9*$I31 | Y31: =1.5*J31 | Z31: Lognormal | AA31: =0.9*K31 | AB31: =1.3*K31 | AC31: Lognormal | AD31: 0.1 | AE31: 1 | AF31: 0 | AG31: Truncated Normal
A32: 213.7 | B32: =IF(ISNUMBER(A32), IF(AND(A32=INT(A32), MOD(A32, 10) = 0), 0, IF(AND(A32=INT(A32), LEN(A32)=2), 1, IF(AND(A32=INT(A32), LEN(A32)=3), 2, LEN(A32) - FIND(".", A32) + 2) ) ), "") | C32: Manufacturing Facility Admin Building | D32: =REPT(" ", B32*2) & C32
A33: 213.71 | B33: =IF(ISNUMBER(A33), IF(AND(A33=INT(A33), MOD(A33, 10) = 0), 0, IF(AND(A33=INT(A33), LEN(A33)=2), 1, IF(AND(A33=INT(A33), LEN(A33)=3), 2, LEN(A33) - FIND(".", A33) + 2) ) ), "") | C33: =_xlfn.CONCAT(C32," Roof") | D33: =REPT(" ", B33*2) & C33 | E33: standard | F33: Constant | G33: 1 | K33: =1200 | L33: $/m^3 | M33: =_xlfn.CONCAT(C33, " Volume") | O33: m^3 | Q33: 2024 | R33: Lab and Mat and Equip | S33: RSMeans software: a tool that primarily provides costs for non-nuclear work Nuclear Multiplier have not been applied | T33: GORDIAN. (2024). "RSMeans data. & Delene, J. G. and I. Hudson, C. R. (1993). Cost estimate guidelines for advanced nuclear power technologies. United States, Oak Ridge National Lab. (ORNL), Oak Ridge, TN (United States): Medium: ED; Size: 159 p. | U33: https://www.rsmeans.com/ & https://www.osti.gov/biblio/10176857 | W33: No Learning | X33: =0.9*$I33 | Y33: =1.5*J33 | Z33: Lognormal | AA33: =0.9*K33 | AB33: =1.3*K33 | AC33: Lognormal | AD33: 0.1 | AE33: 1 | AF33: 0 | AG33: Truncated Normal
A34: 213.72 | B34: =IF(ISNUMBER(A34), IF(AND(A34=INT(A34), MOD(A34, 10) = 0), 0, IF(AND(A34=INT(A34), LEN(A34)=2), 1, IF(AND(A34=INT(A34), LEN(A34)=3), 2, LEN(A34) - FIND(".", A34) + 2) ) ), "") | C34: =_xlfn.CONCAT(C32," Basement") | D34: =REPT(" ", B34*2) & C34 | E34: standard | F34: Constant | G34: 1 | K34: =943.9 | L34: $/m^3 | M34: =_xlfn.CONCAT(C34, " Volume") | O34: m^3 | Q34: 2024 | R34: Lab and Mat and Equip | W34: No Learning | X34: =0.9*$I34 | Y34: =1.5*J34 | Z34: Lognormal | AA34: =0.9*K34 | AB34: =1.3*K34 | AC34: Lognormal | AD34: 0.1 | AE34: 1 | AF34: 0 | AG34: Truncated Normal
A35: 213.73 | B35: =IF(ISNUMBER(A35), IF(AND(A35=INT(A35), MOD(A35, 10) = 0), 0, IF(AND(A35=INT(A35), LEN(A35)=2), 1, IF(AND(A35=INT(A35), LEN(A35)=3), 2, LEN(A35) - FIND(".", A35) + 2) ) ), "") | C35: =_xlfn.CONCAT(C32," Walls") | D35: =REPT(" ", B35*2) & C35 | E35: standard | F35: Constant | G35: 1 | K35: =721.21 | L35: $/m^3 | M35: =_xlfn.CONCAT(C35, " Volume") | O35: m^3 | Q35: 2024 | R35: Lab and Mat and Equip | W35: No Learning | X35: =0.9*$I35 | Y35: =1.5*J35 | Z35: Lognormal | AA35: =0.9*K35 | AB35: =1.3*K35 | AC35: Lognormal | AD35: 0.1 | AE35: 1 | AF35: 0 | AG35: Truncated Normal
A36: 213.79 | B36: =IF(ISNUMBER(A36), IF(AND(A36=INT(A36), MOD(A36, 10) = 0), 0, IF(AND(A36=INT(A36), LEN(A36)=2), 1, IF(AND(A36=INT(A36), LEN(A36)=3), 2, LEN(A36) - FIND(".", A36) + 2) ) ), "") | C36: HVAC | D36: =REPT(" ", B36*2) & C36 | E36: standard | F36: Constant | G36: 1 | L36: $/m^3 | M36: =_xlfn.CONCAT(C32, " Volume") | O36: m^3 | W36: No Learning | X36: =0.9*$I36 | Y36: =1.5*J36 | Z36: Lognormal | AA36: =0.9*K36 | AB36: =1.3*K36 | AC36: Lognormal | AD36: 0.1 | AE36: 1 | AF36: 0 | AG36: Truncated Normal
A37: 213.8 | B37: =IF(ISNUMBER(A37), IF(AND(A37=INT(A37), MOD(A37, 10) = 0), 0, IF(AND(A37=INT(A37), LEN(A37)=2), 1, IF(AND(A37=INT(A37), LEN(A37)=3), 2, LEN(A37) - FIND(".", A37) + 2) ) ), "") | C37: Manufacturing Facility Security Building | D37: =REPT(" ", B37*2) & C37
A38: 213.81 | B38: =IF(ISNUMBER(A38), IF(AND(A38=INT(A38), MOD(A38, 10) = 0), 0, IF(AND(A38=INT(A38), LEN(A38)=2), 1, IF(AND(A38=INT(A38), LEN(A38)=3), 2, LEN(A38) - FIND(".", A38) + 2) ) ), "") | C38: =_xlfn.CONCAT(C37," Roof") | D38: =REPT(" ", B38*2) & C38 | E38: standard | F38: Constant | G38: 1 | K38: =1200 | L38: $/m^3 | M38: =_xlfn.CONCAT(C38, " Volume") | O38: m^3 | Q38: 2024 | R38: Lab and Mat and Equip | S38: RSMeans software: a tool that primarily provides costs for non-nuclear work Nuclear Multiplier have not been applied | T38: GORDIAN. (2024). "RSMeans data. & Delene, J. G. and I. Hudson, C. R. (1993). Cost estimate guidelines for advanced nuclear power technologies. United States, Oak Ridge National Lab. (ORNL), Oak Ridge, TN (United States): Medium: ED; Size: 159 p. | U38: https://www.rsmeans.com/ & https://www.osti.gov/biblio/10176857 | W38: No Learning | X38: =0.9*$I38 | Y38: =1.5*J38 | Z38: Lognormal | AA38: =0.9*K38 | AB38: =1.3*K38 | AC38: Lognormal | AD38: 0.1 | AE38: 1 | AF38: 0 | AG38: Truncated Normal
A39: 213.82 | B39: =IF(ISNUMBER(A39), IF(AND(A39=INT(A39), MOD(A39, 10) = 0), 0, IF(AND(A39=INT(A39), LEN(A39)=2), 1, IF(AND(A39=INT(A39), LEN(A39)=3), 2, LEN(A39) - FIND(".", A39) + 2) ) ), "") | C39: =_xlfn.CONCAT(C37," Basement") | D39: =REPT(" ", B39*2) & C39 | E39: standard | F39: Constant | G39: 1 | K39: =943.9 | L39: $/m^3 | M39: =_xlfn.CONCAT(C39, " Volume") | O39: m^3 | Q39: 2024 | R39: Lab and Mat and Equip | W39: No Learning | X39: =0.9*$I39 | Y39: =1.5*J39 | Z39: Lognormal | AA39: =0.9*K39 | AB39: =1.3*K39 | AC39: Lognormal | AD39: 0.1 | AE39: 1 | AF39: 0 | AG39: Truncated Normal
A40: 213.83 | B40: =IF(ISNUMBER(A40), IF(AND(A40=INT(A40), MOD(A40, 10) = 0), 0, IF(AND(A40=INT(A40), LEN(A40)=2), 1, IF(AND(A40=INT(A40), LEN(A40)=3), 2, LEN(A40) - FIND(".", A40) + 2) ) ), "") | C40: =_xlfn.CONCAT(C37," Walls") | D40: =REPT(" ", B40*2) & C40 | E40: standard | F40: Constant | G40: 1 | K40: =721.21 | L40: $/m^3 | M40: =_xlfn.CONCAT(C40, " Volume") | O40: m^3 | Q40: 2024 | R40: Lab and Mat and Equip | W40: No Learning | X40: =0.9*$I40 | Y40: =1.5*J40 | Z40: Lognormal | AA40: =0.9*K40 | AB40: =1.3*K40 | AC40: Lognormal | AD40: 0.1 | AE40: 1 | AF40: 0 | AG40: Truncated Normal
...
