Workbook
Name CRF: #REF!
Name DiscountRate: #REF!
Name FacilityLifetime: #REF!
Name GeneralDataManufacturingLocations: #REF!
Name MaterialData316SSStandardDensity: #REF!
Name MaterialDataA36CSStandardDensity: #REF!
Name MaterialDataB4CNaturalTheoreticalDensity: #REF!
Name MaterialDataConcreteNominalSolidDensity: #REF!
Name MaterialDataGeneralInsulationStandardDensity: #REF!
Name MaterialDataGR22StandardDensity: #REF!
Name MaterialDataInconel718StandardDensity: #REF!
Name UC_m_in: #REF!

Sheet Cost Database
A1: Account | B1: Level | C1: Account Name | D1: Account Title | E1: Standard Cost Equation? | F1: Optional Variable | G1: Optional Value | H1: Sec Optional Variable | I1: Sec Optional Value | J1: Fixed Cost ($) | K1: Unit Cost | L1: Unit Cost (units) | M1: Scaling Variable | N1: Scaling Variable Ref Value | O1: Units | P1: Exponent | Q1: Dollar Year | R1: Type | S1: Source | T1: Ref | U1: Link | V1: Notes | W1: FOAK to NOAK Multiplier Type | X1: Fixed Cost Low End | Y1: Fixed Cost High End | Z1: Fixed Cost Distribution | AA1: Unit Cost Low End | AB1: Unit Cost High End | AC1: Unit Cost Distribution | AD1: Exponent std | AE1: Exponent Max | AF1: Exponent Min | AG1: Exponent Distribution
A2: 10 | B2: =IF(ISNUMBER(A2), IF(AND(A2=INT(A2), MOD(A2, 10) = 0), 0, IF(AND(A2=INT(A2), LEN(A2)=2), 1, IF(AND(A2=INT(A2), LEN(A2)=3), 2, LEN(A2) - FIND(".", A2) + 2) ) ), "") -> 0 | C2: Capitalized Pre-Construction Costs | D2: =REPT(" ", B2*2) & C2 -> Capitalized Pre-Construction Costs
A3: 11 | B3: =IF(ISNUMBER(A3), IF(AND(A3=INT(A3), MOD(A3, 10) = 0), 0, IF(AND(A3=INT(A3), LEN(A3)=2), 1, IF(AND(A3=INT(A3), LEN(A3)=3), 2, LEN(A3) - FIND(".", A3) + 2) ) ), "") -> 1 | C3: Land Cost | D3: =REPT(" ", B3*2) & C3 -> Land Cost | E3: standard | K3: 3800 | L3: $/acres | M3: Land Area | O3: acres | Q3: 2022 | R3: General | S3: The average cost per acre for rural land in 2022 from the US Department of Agriculture | T3: Abou-Jaoude, A., Lohse, C. S., Larsen, L. M., Guaita, N., Trivedi, I., Joseck, F. C., ... & Stein, A. (2024). Meta-analysis of advanced nuclear reactor cost estimations (No. INL/RPT-24-77048-Rev001). Idaho National Laboratory (INL), Idaho Falls, ID (United States). | U3: https://inldigitallibrary.inl.gov/sites/sti/sti/Sort_107010.pdf | W3: No Learning | X3: =0.9*$J3 -> 0 | Y3: =1.5*J3 -> 0 | Z3: Lognormal | AA3: =0.9*K3 -> 3420 | AB3: =1.3*K3 -> 4940 | AC3: Lognormal | AD3: 0.1 | AE3: 1 | AF3: 0 | AG3: Truncated Normal
A4: 12 | B4: =IF(ISNUMBER(A4), IF(AND(A4=INT(A4), MOD(A4, 10) = 0), 0, IF(AND(A4=INT(A4), LEN(A4)=2), 1, IF(AND(A4=INT(A4), LEN(A4)=3), 2, LEN(A4) - FIND(".", A4) + 2) ) ), "") -> 1 | C4: Site Permits | D4: =REPT(" ", B4*2) & C4 -> Site Permits | E4: standard | K4: =10.03*1000 -> 10030 | L4: $/MWe | M4: Power MWe | O4: MWe | Q4: 2022 | R4: Labor | S4: Data from SMR MHTGRs | W4: No Learning | X4: =0.9*$J4 -> 0 | Y4: =1.5*J4 -> 0 | Z4: Lognormal | AA4: =0.9*K4 -> 9027 | AB4: =1.3*K4 -> 13039 | AC4: Lognormal | AD4: 0.1 | AE4: 1 | AF4: 0 | AG4: Truncated Normal
A5: 13 | B5: =IF(ISNUMBER(A5), IF(AND(A5=INT(A5), MOD(A5, 10) = 0), 0, IF(AND(A5=INT(A5), LEN(A5)=2), 1, IF(AND(A5=INT(A5), LEN(A5)=3), 2, LEN(A5) - FIND(".", A5) + 2) ) ), "") -> 1 | C5: Plant Licensing | D5: =REPT(" ", B5*2) & C5 -> Plant Licensing | E5: standard | J5: =0.5*(X5+Y5) -> 27025000 | Q5: 2024 | R5: Labor | S5: NRC Website | T5: Using data from the NRC website that the cost is between 45 and 70M https://www.nrc.gov/about-nrc/regulatory/licensing/general-fee-questions.pdf Also, using recent change to the NRC fees by a factor of 0.47 https://ignition-news.com/the-nrc-passes-new-rules-for-advanced-reactor-companies/#:~:text=Under%20a%20rule%20published%20in,2024%2C%20which%20takes%20effect%20Oct. | U5: https://art.inl.gov/NGNP/INL%20Documents/Year%202012/Assessment%20of%20High%20Temperature%20Gas-Cooled%20Reactor%20-%20HTGR%20-%20Capital%20and%20Operating%20Costs.pdf | W5: Licensing Learning | X5: =0.47*45*1000000 -> 21150000 | Y5: =0.47*70*1000000 -> 32900000 | Z5: Uniform | AA5: =0.9*K5 -> 0 | AB5: =1.3*K5 -> 0 | AC5: Lognormal | AD5: 0.1 | AE5: 1 | AF5: 0 | AG5: Truncated Normal
A6: 14 | B6: =IF(ISNUMBER(A6), IF(AND(A6=INT(A6), MOD(A6, 10) = 0), 0, IF(AND(A6=INT(A6), LEN(A6)=2), 1, IF(AND(A6=INT(A6), LEN(A6)=3), 2, LEN(A6) - FIND(".", A6) + 2) ) ), "") -> 1 | C6: Plant Permits | D6: =REPT(" ", B6*2) & C6 -> Plant Permits | E6: standard | J6: 3000000 | Q6: 2009 | R6: Labor | S6: NGNP project | T6: Gandrik, A., B. Wallace, L. Demick, S. Melancon and M. Patterson (2011). "Assessment of high temperature gas-cooled reactor (HTGR) capital and operating costs." Idaho National Laboratory, TEV-1196, Idaho Falls, ID. | W6: No Learning | X6: =0.9*$J6 -> 2700000 | Y6: =1.5*J6 -> 4500000 | Z6: Lognormal | AA6: =0.9*K6 -> 0 | AB6: =1.3*K6 -> 0 | AC6: Lognormal | AD6: 0.1 | AE6: 1 | AF6: 0 | AG6: Truncated Normal
A7: 15 | B7: =IF(ISNUMBER(A7), IF(AND(A7=INT(A7), MOD(A7, 10) = 0), 0, IF(AND(A7=INT(A7), LEN(A7)=2), 1, IF(AND(A7=INT(A7), LEN(A7)=3), 2, LEN(A7) - FIND(".", A7) + 2) ) ), "") -> 1 | C7: Plant Studies | D7: =REPT(" ", B7*2) & C7 -> Plant Studies | E7: standard | J7: =MARVEL_Cost!C4 -> 5210451 | Q7: 2024 | R7: Labor | S7: MARVEL Project (Labor-adjusted Cost) | T7: Hanna, B. N., Gonzaga de Oliveira, R. G., Mohammad Al Dawood, K. A., Patterson, M. D., Abou Jaoude, A., & Garcia, S. (2024). Technoeconomic Evaluation of Microreactor Using Detailed Bottom-up Estimate (No. INL/RPT-24-80433-Rev000). Idaho National Laboratory (INL), Idaho Falls, ID (United States). | U7: https://inldigitallibrary.inl.gov/sites/sti/sti/Sort_129862.pdf | V7: MARVEL's data were updated | W7: No Learning | X7: =0.9*$J7 -> 4689405.9 | Y7: =1.5*J7 -> 7815676.5 | Z7: Lognormal | AA7: =0.9*K7 -> 0 | AB7: =1.3*K7 -> 0 | AC7: Lognormal | AD7: 0.1 | AE7: 1 | AF7: 0 | AG7: Truncated Normal
A8: 20 | B8: =IF(ISNUMBER(A8), IF(AND(A8=INT(A8), MOD(A8, 10) = 0), 0, IF(AND(A8=INT(A8), LEN(A8)=2), 1, IF(AND(A8=INT(A8), LEN(A8)=3), 2, LEN(A8) - FIND(".", A8) + 2) ) ), "") -> 0 | C8: Capitalized Direct Costs | D8: =REPT(" ", B8*2) & C8 -> Capitalized Direct Costs
A9: 21 | B9: =IF(ISNUMBER(A9), IF(AND(A9=INT(A9), MOD(A9, 10) = 0), 0, IF(AND(A9=INT(A9), LEN(A9)=2), 1, IF(AND(A9=INT(A9), LEN(A9)=3), 2, LEN(A9) - FIND(".", A9) + 2) ) ), "") -> 1 | C9: Structures and Improvements | D9: =REPT(" ", B9*2) & C9 -> Structures and Improvements
A10: 211 | B10: =IF(ISNUMBER(A10), IF(AND(A10=INT(A10), MOD(A10, 10) = 0), 0, IF(AND(A10=INT(A10), LEN(A10)=2), 1, IF(AND(A10=INT(A10), LEN(A10)=3), 2, LEN(A10) - FIND(".", A10) + 2) ) ), "") -> 2 | C10: Site Preparation/ Yard Work | D10: =REPT(" ", B10*2) & C10 -> Site Preparation/ Yard Work
A11: 211.1 | B11: =IF(ISNUMBER(A11), IF(AND(A11=INT(A11), MOD(A11, 10) = 0), 0, IF(AND(A11=INT(A11), LEN(A11)=2), 1, IF(AND(A11=INT(A11), LEN(A11)=3), 2, LEN(A11) - FIND(".", A11) + 2) ) ), "") -> 3 | C11: Cleaning and Grubbing | D11: =REPT(" ", B11*2) & C11 -> Cleaning and Grubbing | E11: standard | K11: =4408.18*1.33 -> 5862.8794 | L11: $/acres | M11: Land Area | O11: acres | Q11: 2024 | R11: Lab and Equip | S11: RSMeans software: a tool that primarily provides costs for non-nuclear work Nuclear Multiplier have been applied to adjust the costs for nuclear-site-related work | T11: GORDIAN. (2024). "RSMeans data. & Delene, J. G. and I. Hudson, C. R. (1993). Cost estimate guidelines for advanced nuclear power technologies. United States, Oak Ridge National Lab. (ORNL), Oak Ridge, TN (United States): Medium: ED; Size: 159 p. | U11: https://www.rsmeans.com/ & https://www.osti.gov/biblio/10176857 | W11: Onsite Learning | X11: =0.9*$J11 -> 0 | Y11: =1.5*J11 -> 0 | Z11: Lognormal | AA11: =0.9*K11 -> 5276.5915 | AB11: =1.3*K11 -> 7621.7432 | AC11: Lognormal | AD11: 0.1 | AE11: 1 | AF11: 0 | AG11: Truncated Normal
A12: 211.2 | B12: =IF(ISNUMBER(A12), IF(AND(A12=INT(A12), MOD(A12, 10) = 0), 0, IF(AND(A12=INT(A12), LEN(A12)=2), 1, IF(AND(A12=INT(A12), LEN(A12)=3), 2, LEN(A12) - FIND(".", A12) + 2) ) ), "") -> 3 | C12: Stripping Topsoil | D12: =REPT(" ", B12*2) & C12 -> Stripping Topsoil | E12: standard | K12: =2565.2*1.33 -> 3411.716 | L12: $/acres | M12: Land Area | O12: acres | Q12: 2024 | R12: Lab and Equip | W12: Onsite Learning | X12: =0.9*$J12 -> 0 | Y12: =1.5*J12 -> 0 | Z12: Lognormal | AA12: =0.9*K12 -> 3070.5444 | AB12: =1.3*K12 -> 4435.2308 | AC12: Lognormal | AD12: 0.1 | AE12: 1 | AF12: 0 | AG12: Truncated Normal
A13: 211.3 | B13: =IF(ISNUMBER(A13), IF(AND(A13=INT(A13), MOD(A13, 10) = 0), 0, IF(AND(A13=INT(A13), LEN(A13)=2), 1, IF(AND(A13=INT(A13), LEN(A13)=3), 2, LEN(A13) - FIND(".", A13) + 2) ) ), "") -> 3 | C13: Excavation | D13: =REPT(" ", B13*2) & C13 -> Excavation | E13: standard | K13: =22.86*1.4 -> 32.004 | L13: $/m^3 | M13: Excavation Volume | O13: m^3 | Q13: 2024 | R13: Lab and Equip | W13: Onsite Learning | X13: =0.9*$J13 -> 0 | Y13: =1.5*J13 -> 0 | Z13: Lognormal | AA13: =0.9*K13 -> 28.8036 | AB13: =1.3*K13 -> 41.6052 | AC13: Lognormal | AD13: 0.1 | AE13: 1 | AF13: 0 | AG13: Truncated Normal
A14: 212 | B14: =IF(ISNUMBER(A14), IF(AND(A14=INT(A14), MOD(A14, 10) = 0), 0, IF(AND(A14=INT(A14), LEN(A14)=2), 1, IF(AND(A14=INT(A14), LEN(A14)=3), 2, LEN(A14) - FIND(".", A14) + 2) ) ), "") -> 2 | C14: Reactor Island Civil Structures | D14: =REPT(" ", B14*2) & C14 -> Reactor Island Civil Structures
A15: 212.1 | B15: =IF(ISNUMBER(A15), IF(AND(A15=INT(A15), MOD(A15, 10) = 0), 0, IF(AND(A15=INT(A15), LEN(A15)=2), 1, IF(AND(A15=INT(A15), LEN(A15)=3), 2, LEN(A15) - FIND(".", A15) + 2) ) ), "") -> 3 | C15: Reactor Building Slab Roof | D15: =REPT(" ", B15*2) & C15 -> Reactor Building Slab Roof | E15: standard | K15: =1200 *1.53 -> 1836 | L15: $/m^3 | M15: Reactor Building Slab Roof Volume | O15: m^3 | Q15: 2024 | R15: Lab and Mat and Equip | S15: RSMeans software: a tool that primarily provides costs for non-nuclear work Nuclear Multiplier have been applied to adjust the costs for nuclear-site-related work | T15: GORDIAN. (2024). "RSMeans data. & Delene, J. G. and I. Hudson, C. R. (1993). Cost estimate guidelines for advanced nuclear power technologies. United States, Oak Ridge National Lab. (ORNL), Oak Ridge, TN (United States): Medium: ED; Size: 159 p. | U15: https://www.rsmeans.com/ & https://www.osti.gov/biblio/10176857 | W15: Onsite Learning | X15: =0.9*$J15 -> 0 | Y15: =1.5*J15 -> 0 | Z15: Lognormal | AA15: =0.9*K15 -> 1652.4 | AB15: =1.3*K15 -> 2386.8 | AC15: Lognormal | AD15: 0.1 | AE15: 1 | AF15: 0 | AG15: Truncated Normal
A16: 212.2 | B16: =IF(ISNUMBER(A16), IF(AND(A16=INT(A16), MOD(A16, 10) = 0), 0, IF(AND(A16=INT(A16), LEN(A16)=2), 1, IF(AND(A16=INT(A16), LEN(A16)=3), 2, LEN(A16) - FIND(".", A16) + 2) ) ), "") -> 3 | C16: Reactor Building Basement | D16: =REPT(" ", B16*2) & C16 -> Reactor Building Basement | E16: standard | K16: =943.9*1.53 -> 1444.167 | L16: $/m^3 | M16: Reactor Building Basement Volume | O16: m^3 | Q16: 2024 | R16: Lab and Mat and Equip | W16: Onsite Learning | X16: =0.9*$J16 -> 0 | Y16: =1.5*J16 -> 0 | Z16: Lognormal | AA16: =0.9*K16 -> 1299.7503 | AB16: =1.3*K16 -> 1877.4171 | AC16: Lognormal | AD16: 0.1 | AE16: 1 | AF16: 0 | AG16: Truncated Normal
A17: 212.3 | B17: =IF(ISNUMBER(A17), IF(AND(A17=INT(A17), MOD(A17, 10) = 0), 0, IF(AND(A17=INT(A17), LEN(A17)=2), 1, IF(AND(A17=INT(A17), LEN(A17)=3), 2, LEN(A17) - FIND(".", A17) + 2) ) ), "") -> 3 | C17: Reactor Building Walls | D17: =REPT(" ", B17*2) & C17 -> Reactor Building Walls | E17: standard | K17: =721.21*1.53 -> 1103.4513 | L17: $/m^3 | M17: Reactor Building Exterior Walls Volume | O17: m^3 | Q17: 2024 | R17: Lab and Mat and Equip | W17: Onsite Learning | X17: =0.9*$J17 -> 0 | Y17: =1.5*J17 -> 0 | Z17: Lognormal | AA17: =0.9*K17 -> 993.10617 | AB17: =1.3*K17 -> 1434.4867 | AC17: Lognormal | AD17: 0.1 | AE17: 1 | AF17: 0 | AG17: Truncated Normal
A18: 212.4 | B18: =IF(ISNUMBER(A18), IF(AND(A18=INT(A18), MOD(A18, 10) = 0), 0, IF(AND(A18=INT(A18), LEN(A18)=2), 1, IF(AND(A18=INT(A18), LEN(A18)=3), 2, LEN(A18) - FIND(".", A18) + 2) ) ), "") -> 3 | C18: Reactor Building Liner | D18: =REPT(" ", B18*2) & C18 -> Reactor Building Liner | E18: standard | K18: =60848829/9373 -> 6491.9267 | L18: $/m^2 | M18: Reactor Building Superstructure Area | N18: 9373 | O18: m^2 | P18: 1 | Q18: 2018 | R18: Lab and Mat and Equip | S18: Stewart W.R., Shirvan K., "Capital cost estimation for advanced nuclear power plants," Renewable and Sustainable Energy Reviews, Nov. 2021, 111880 | T18: Stewart W.R., Shirvan K., "Capital cost estimation for advanced nuclear power plants," Renewable and Sustainable Energy Reviews, Nov. 2021, 111880 | U18: https://doi.org/10.1016/j.rser.2021.111880 | W18: Onsite Learning | X18: =0.9*$J18 -> 0 | Y18: =1.5*J18 -> 0 | Z18: Lognormal | AA18: =0.9*K18 -> 5842.734 | AB18: =1.3*K18 -> 8439.5047 | AC18: Lognormal | AD18: 0.1 | AE18: 1 | AF18: 0 | AG18: Truncated Normal
A19: 212.5 | B19: =IF(ISNUMBER(A19), IF(AND(A19=INT(A19), MOD(A19, 10) = 0), 0, IF(AND(A19=INT(A19), LEN(A19)=2), 1, IF(AND(A19=INT(A19), LEN(A19)=3), 2, LEN(A19) - FIND(".", A19) + 2) ) ), "") -> 3 | C19: Reactor Building HVAC | D19: =REPT(" ", B19*2) & C19 -> Reactor Building HVAC | E19: standard | K19: =5917967/N19 -> 1731.9189 | L19: $/MWt | M19: Power MWt | N19: 3417 | O19: MWt | P19: 0.8 | Q19: 2018 | R19: Lab and Mat and Equip | S19: Stewart W.R., Shirvan K., "Capital cost estimation for advanced nuclear power plants," Renewable and Sustainable Energy Reviews, Nov. 2021, 111880 | T19: Stewart W.R., Shirvan K., "Capital cost estimation for advanced nuclear power plants," Renewable and Sustainable Energy Reviews, Nov. 2021, 111880 | U19: https://doi.org/10.1016/j.rser.2021.111880 | W19: Onsite Learning | X19: =0.9*$J19 -> 0 | Y19: =1.5*J19 -> 0 | Z19: Lognormal | AA19: =0.9*K19 -> 1558.727 | AB19: =1.3*K19 -> 2251.4946 | AC19: Lognormal | AD19: 0.1 | AE19: 1 | AF19: 0 | AG19: Truncated Normal
A20: 213 | B20: =IF(ISNUMBER(A20), IF(AND(A20=INT(A20), MOD(A20, 10) = 0), 0, IF(AND(A20=INT(A20), LEN(A20)=2), 1, IF(AND(A20=INT(A20), LEN(A20)=3), 2, LEN(A20) - FIND(".", A20) + 2) ) ), "") -> 2 | C20: Main Function Buildings | D20: =REPT(" ", B20*2) & C20 -> Main Function Buildings
A21: 213.1 | B21: =IF(ISNUMBER(A21), IF(AND(A21=INT(A21), MOD(A21, 10) = 0), 0, IF(AND(A21=INT(A21), LEN(A21)=2), 1, IF(AND(A21=INT(A21), LEN(A21)=3), 2, LEN(A21) - FIND(".", A21) + 2) ) ), "") -> 3 | C21: Energy conversion Building | D21: =REPT(" ", B21*2) & C21 -> Energy conversion Building
A22: 213.11 | B22: =IF(ISNUMBER(A22), IF(AND(A22=INT(A22), MOD(A22, 10) = 0), 0, IF(AND(A22=INT(A22), LEN(A22)=2), 1, IF(AND(A22=INT(A22), LEN(A22)=3), 2, LEN(A22) - FIND(".", A22) + 2) ) ), "") -> 4 | C22: Energy Conversion Building Slab Roof | D22: =REPT(" ", B22*2) & C22 -> Energy Conversion Building Slab Roof | E22: standard | K22: =1200 -> 1200 | L22: $/m^3 | M22: Turbine Building Slab Roof Volume | O22: m^3 | Q22: 2024 | R22: Lab and Mat and Equip | S22: RSMeans software: a tool that primarily provides costs for non-nuclear work | T22: GORDIAN. (2024). "RSMeans data. & Delene, J. G. and I. Hudson, C. R. (1993). Cost estimate guidelines for advanced nuclear power technologies. United States, Oak Ridge National Lab. (ORNL), Oak Ridge, TN (United States): Medium: ED; Size: 159 p. | U22: https://www.rsmeans.com/ & https://www.osti.gov/biblio/10176857 | W22: Onsite Learning | X22: =0.9*$J22 -> 0 | Y22: =1.5*J22 -> 0 | Z22: Lognormal | AA22: =0.9*K22 -> 1080 | AB22: =1.3*K22 -> 1560 | AC22: Lognormal | AD22: 0.1 | AE22: 1 | AF22: 0 | AG22: Truncated Normal
A23: 213.12 | B23: =IF(ISNUMBER(A23), IF(AND(A23=INT(A23), MOD(A23, 10) = 0), 0, IF(AND(A23=INT(A23), LEN(A23)=2), 1, IF(AND(A23=INT(A23), LEN(A23)=3), 2, LEN(A23) - FIND(".", A23) + 2) ) ), "") -> 4 | C23: Energy Conversion Building Basement | D23: =REPT(" ", B23*2) & C23 -> Energy Conversion Building Basement | E23: standard | K23: =943.9 -> 943.9 | L23: $/m^3 | M23: Turbine Building Basement Volume | O23: m^3 | Q23: 2024 | R23: Lab and Mat and Equip | W23: Onsite Learning | X23: =0.9*$J23 -> 0 | Y23: =1.5*J23 -> 0 | Z23: Lognormal | AA23: =0.9*K23 -> 849.51 | AB23: =1.3*K23 -> 1227.07 | AC23: Lognormal | AD23: 0.1 | AE23: 1 | AF23: 0 | AG23: Truncated Normal
A24: 213.13 | B24: =IF(ISNUMBER(A24), IF(AND(A24=INT(A24), MOD(A24, 10) = 0), 0, IF(AND(A24=INT(A24), LEN(A24)=2), 1, IF(AND(A24=INT(A24), LEN(A24)=3), 2, LEN(A24) - FIND(".", A24) + 2) ) ), "") -> 4 | C24: Energy Conversion Building Walls | D24: =REPT(" ", B24*2) & C24 -> Energy Conversion Building Walls | E24: standard | K24: =721.21 -> 721.21 | L24: $/m^3 | M24: Turbine Building Exterior Walls Volume | O24: m^3 | Q24: 2024 | R24: Lab and Mat and Equip | W24: Onsite Learning | X24: =0.9*$J24 -> 0 | Y24: =1.5*J24 -> 0 | Z24: Lognormal | AA24: =0.9*K24 -> 649.089 | AB24: =1.3*K24 -> 937.573 | AC24: Lognormal | AD24: 0.1 | AE24: 1 | AF24: 0 | AG24: Truncated Normal
A25: 213.2 | B25: =IF(ISNUMBER(A25), IF(AND(A25=INT(A25), MOD(A25, 10) = 0), 0, IF(AND(A25=INT(A25), LEN(A25)=2), 1, IF(AND(A25=INT(A25), LEN(A25)=3), 2, LEN(A25) - FIND(".", A25) + 2) ) ), "") -> 3 | C25: Control building | D25: =REPT(" ", B25*2) & C25 -> Control building
A26: 213.21 | B26: =IF(ISNUMBER(A26), IF(AND(A26=INT(A26), MOD(A26, 10) = 0), 0, IF(AND(A26=INT(A26), LEN(A26)=2), 1, IF(AND(A26=INT(A26), LEN(A26)=3), 2, LEN(A26) - FIND(".", A26) + 2) ) ), "") -> 4 | C26: Control Building Slab Roof | D26: =REPT(" ", B26*2) & C26 -> Control Building Slab Roof | E26: standard | K26: =1200 -> 1200 | L26: $/m^3 | M26: Control Building Slab Roof Volume | O26: m^3 | Q26: 2024 | R26: Lab and Mat and Equip | S26: RSMeans software: a tool that primarily provides costs for non-nuclear work | T26: GORDIAN. (2024). "RSMeans data. & Delene, J. G. and I. Hudson, C. R. (1993). Cost estimate guidelines for advanced nuclear power technologies. United States, Oak Ridge National Lab. (ORNL), Oak Ridge, TN (United States): Medium: ED; Size: 159 p. | U26: https://www.rsmeans.com/ & https://www.osti.gov/biblio/10176857 | W26: Onsite Learning | X26: =0.9*$J26 -> 0 | Y26: =1.5*J26 -> 0 | Z26: Lognormal | AA26: =0.9*K26 -> 1080 | AB26: =1.3*K26 -> 1560 | AC26: Lognormal | AD26: 0.1 | AE26: 1 | AF26: 0 | AG26: Truncated Normal
A27: 213.22 | B27: =IF(ISNUMBER(A27), IF(AND(A27=INT(A27), MOD(A27, 10) = 0), 0, IF(AND(A27=INT(A27), LEN(A27)=2), 1, IF(AND(A27=INT(A27), LEN(A27)=3), 2, LEN(A27) - FIND(".", A27) + 2) ) ), "") -> 4 | C27: Control Building Basement | D27: =REPT(" ", B27*2) & C27 -> Control Building Basement | E27: standard | K27: =943.9 -> 943.9 | L27: $/m^3 | M27: Control Building Basement Volume | O27: m^3 | Q27: 2024 | R27: Lab and Mat and Equip | W27: Onsite Learning | X27: =0.9*$J27 -> 0 | Y27: =1.5*J27 -> 0 | Z27: Lognormal | AA27: =0.9*K27 -> 849.51 | AB27: =1.3*K27 -> 1227.07 | AC27: Lognormal | AD27: 0.1 | AE27: 1 | AF27: 0 | AG27: Truncated Normal
A28: 213.23 | B28: =IF(ISNUMBER(A28), IF(AND(A28=INT(A28), MOD(A28, 10) = 0), 0, IF(AND(A28=INT(A28), LEN(A28)=2), 1, IF(AND(A28=INT(A28), LEN(A28)=3), 2, LEN(A28) - FIND(".", A28) + 2) ) ), "") -> 4 | C28: Control Building Walls | D28: =REPT(" ", B28*2) & C28 -> Control Building Walls | E28: standard | K28: =721.21 -> 721.21 | L28: $/m^3 | M28: Control Building Exterior Walls Volume | O28: m^3 | Q28: 2024 | R28: Lab and Mat and Equip | W28: Onsite Learning | X28: =0.9*$J28 -> 0 | Y28: =1.5*J28 -> 0 | Z28: Lognormal | AA28: =0.9*K28 -> 649.089 | AB28: =1.3*K28 -> 937.573 | AC28: Lognormal | AD28: 0.1 | AE28: 1 | AF28: 0 | AG28: Truncated Normal
A29: 213.3 | B29: =IF(ISNUMBER(A29), IF(AND(A29=INT(A29), MOD(A29, 10) = 0), 0, IF(AND(A29=INT(A29), LEN(A29)=2), 1, IF(AND(A29=INT(A29), LEN(A29)=3), 2, LEN(A29) - FIND(".", A29) + 2) ) ), "") -> 3 | C29: Integrated Heat Exchanger Building | D29: =REPT(" ", B29*2) & C29 -> Integrated Heat Exchanger Building | F29: reactor type | G29: GCMR
A30: 213.31 | B30: =IF(ISNUMBER(A30), IF(AND(A30=INT(A30), MOD(A30, 10) = 0), 0, IF(AND(A30=INT(A30), LEN(A30)=2), 1, IF(AND(A30=INT(A30), LEN(A30)=3), 2, LEN(A30) - FIND(".", A30) + 2) ) ), "") -> 4 | C30: Integrated Heat Exchanger Building Slab Roof | D30: =REPT(" ", B30*2) & C30 -> Integrated Heat Exchanger Building Slab Roof | E30: standard | F30: reactor type | G30: GCMR | K30: =1200 -> 1200 | L30: $/m^3 | M30: Integrated Heat Exchanger Building Slab Roof Volume | O30: m^3 | Q30: 2024 | R30: Lab and Mat and Equip | S30: RSMeans software: a tool that primarily provides costs for non-nuclear work | T30: GORDIAN. (2024). "RSMeans data. & Delene, J. G. and I. Hudson, C. R. (1993). Cost estimate guidelines for advanced nuclear power technologies. United States, Oak Ridge National Lab. (ORNL), Oak Ridge, TN (United States): Medium: ED; Size: 159 p. | U30: https://www.rsmeans.com/ & https://www.osti.gov/biblio/10176857 | W30: Onsite Learning | X30: =0.9*$J30 -> 0 | Y30: =1.5*J30 -> 0 | Z30: Lognormal | AA30: =0.9*K30 -> 1080 | AB30: =1.3*K30 -> 1560 | AC30: Lognormal | AD30: 0.1 | AE30: 1 | AF30: 0 | AG30: Truncated Normal
A31: 213.32 | B31: =IF(ISNUMBER(A31), IF(AND(A31=INT(A31), MOD(A31, 10) = 0), 0, IF(AND(A31=INT(A31), LEN(A31)=2), 1, IF(AND(A31=INT(A31), LEN(A31)=3), 2, LEN(A31) - FIND(".", A31) + 2) ) ), "") -> 4 | C31: Integrated Heat Exchanger Building Basement | D31: =REPT(" ", B31*2) & C31 -> Integrated Heat Exchanger Building Basement | E31: standard | F31: reactor type | G31: GCMR | K31: =943.9 -> 943.9 | L31: $/m^3 | M31: Integrated Heat Exchanger Building Basement Volume | O31: m^3 | Q31: 2024 | R31: Lab and Mat and Equip | W31: Onsite Learning | X31: =0.9*$J31 -> 0 | Y31: =1.5*J31 -> 0 | Z31: Lognormal | AA31: =0.9*K31 -> 849.51 | AB31: =1.3*K31 -> 1227.07 | AC31: Lognormal | AD31: 0.1 | AE31: 1 | AF31: 0 | AG31: Truncated Normal
A32: 213.33 | B32: =IF(ISNUMBER(A32), IF(AND(A32=INT(A32), MOD(A32, 10) = 0), 0, IF(AND(A32=INT(A32), LEN(A32)=2), 1, IF(AND(A32=INT(A32), LEN(A32)=3), 2, LEN(A32) - FIND(".", A32) + 2) ) ), "") -> 4 | C32: Integrated Heat Exchanger Building Walls | D32: =REPT(" ", B32*2) & C32 -> Integrated Heat Exchanger Building Walls | E32: standard | F32: reactor type | G32: GCMR | K32: =721.21 -> 721.21 | L32: $/m^3 | M32: Integrated Heat Exchanger Building Exterior Walls Volume | O32: m^3 | Q32: 2024 | R32: Lab and Mat and Equip | W32: Onsite Learning | X32: =0.9*$J32 -> 0 | Y32: =1.5*J32 -> 0 | Z32: Lognormal | AA32: =0.9*K32 -> 649.089 | AB32: =1.3*K32 -> 937.573 | AC32: Lognormal | AD32: 0.1 | AE32: 1 | AF32: 0 | AG32: Truncated Normal
A33: 213.34 | B33: =IF(ISNUMBER(A33), IF(AND(A33=INT(A33), MOD(A33, 10) = 0), 0, IF(AND(A33=INT(A33), LEN(A33)=2), 1, IF(AND(A33=INT(A33), LEN(A33)=3), 2, LEN(A33) - FIND(".", A33) + 2) ) ), "") -> 4 | C33: Integrated Heat Exchanger Building Liner | D33: =REPT(" ", B33*2) & C33 -> Integrated Heat Exchanger Building Liner | E33: standard | F33: reactor type | G33: GCMR | K33: =60848829/9373 -> 6491.9267 | L33: $/m^2 | M33: Integrated Heat Exchanger Building Superstructure Area | N33: 9373 | O33: m^2 | P33: 1 | Q33: 2018 | R33: Lab and Mat and Equip | S33: Stewart W.R., Shirvan K., "Capital cost estimation for advanced nuclear power plants," Renewable and Sustainable Energy Reviews, Nov. 2021, 111880 | T33: Stewart W.R., Shirvan K., "Capital cost estimation for advanced nuclear power plants," Renewable and Sustainable Energy Reviews, Nov. 2021, 111880 | U33: https://doi.org/10.1016/j.rser.2021.111880 | W33: Onsite Learning | X33: =0.9*$J33 -> 0 | Y33: =1.5*J33 -> 0 | Z33: Lognormal | AA33: =0.9*K33 -> 5842.734 | AB33: =1.3*K33 -> 8439.5047 | AC33: Lognormal | AD33: 0.1 | AE33: 1 | AF33: 0 | AG33: Truncated Normal
A34: 214 | B34: =IF(ISNUMBER(A34), IF(AND(A34=INT(A34), MOD(A34, 10) = 0), 0, IF(AND(A34=INT(A34), LEN(A34)=2), 1, IF(AND(A34=INT(A34), LEN(A34)=3), 2, LEN(A34) - FIND(".", A34) + 2) ) ), "") -> 2 | C34: Buildings to Support Main Function | D34: =REPT(" ", B34*2) & C34 -> Buildings to Support Main Function
A35: 214.1 | B35: =IF(ISNUMBER(A35), IF(AND(A35=INT(A35), MOD(A35, 10) = 0), 0, IF(AND(A35=INT(A35), LEN(A35)=2), 1, IF(AND(A35=INT(A35), LEN(A35)=3), 2, LEN(A35) - FIND(".", A35) + 2) ) ), "") -> 3 | C35: Fuel Management Buildings | D35: =REPT(" ", B35*2) & C35 -> Fuel Management Buildings
A36: 214.11 | B36: =IF(ISNUMBER(A36), IF(AND(A36=INT(A36), MOD(A36, 10) = 0), 0, IF(AND(A36=INT(A36), LEN(A36)=2), 1, IF(AND(A36=INT(A36), LEN(A36)=3), 2, LEN(A36) - FIND(".", A36) + 2) ) ), "") -> 4 | C36: Refueling Building | D36: =REPT(" ", B36*2) & C36 -> Refueling Building
A37: 214.111 | B37: =IF(ISNUMBER(A37), IF(AND(A37=INT(A37), MOD(A37, 10) = 0), 0, IF(AND(A37=INT(A37), LEN(A37)=2), 1, IF(AND(A37=INT(A37), LEN(A37)=3), 2, LEN(A37) - FIND(".", A37) + 2) ) ), "") -> 5 | C37: Refueling Building Slab Roof | D37: =REPT(" ", B37*2) & C37 -> Refueling Building Slab Roof | E37: standard | K37: =1200 *1.53 -> 1836 | L37: $/m^3 | M37: Refueling Building Slab Roof Volume | O37: m^3 | Q37: 2024 | R37: Lab and Mat and Equip | S37: RSMeans software: a tool that primarily provides costs for non-nuclear work Nuclear Multiplier have been applied to adjust the costs for nuclear-site-related work | T37: GORDIAN. (2024). "RSMeans data. & Delene, J. G. and I. Hudson, C. R. (1993). Cost estimate guidelines for advanced nuclear power technologies. United States, Oak Ridge National Lab. (ORNL), Oak Ridge, TN (United States): Medium: ED; Size: 159 p. | U37: https://www.rsmeans.com/ & https://www.osti.gov/biblio/10176857 | W37: Onsite Learning | X37: =0.9*$J37 -> 0 | Y37: =1.5*J37 -> 0 | AA37: =0.9*K37 -> 1652.4 | AB37: =1.3*K37 -> 2386.8 | AC37: Lognormal | AD37: 0.1 | AE37: 1 | AF37: 0 | AG37: Truncated Normal
A38: 214.112 | B38: =IF(ISNUMBER(A38), IF(AND(A38=INT(A38), MOD(A38, 10) = 0), 0, IF(AND(A38=INT(A38), LEN(A38)=2), 1, IF(AND(A38=INT(A38), LEN(A38)=3), 2, LEN(A38) - FIND(".", A38) + 2) ) ), "") -> 5 | C38: Refueling Building Basement | D38: =REPT(" ", B38*2) & C38 -> Refueling Building Basement | E38: standard | K38: =943.9*1.53 -> 1444.167 | L38: $/m^3 | M38: Refueling Building Basement Volume | O38: m^3 | Q38: 2024 | R38: Lab and Mat and Equip | W38: Onsite Learning | X38: =0.9*$J38 -> 0 | Y38: =1.5*J38 -> 0 | Z38: Lognormal | AA38: =0.9*K38 -> 1299.7503 | AB38: =1.3*K38 -> 1877.4171 | AC38: Lognormal | AD38: 0.1 | AE38: 1 | AF38: 0 | AG38: Truncated Normal
A39: 214.113 | B39: =IF(ISNUMBER(A39), IF(AND(A39=INT(A39), MOD(A39, 10) = 0), 0, IF(AND(A39=INT(A39), LEN(A39)=2), 1, IF(AND(A39=INT(A39), LEN(A39)=3), 2, LEN(A39) - FIND(".", A39) + 2) ) ), "") -> 5 | C39: Refueling Building Walls | D39: =REPT(" ", B39*2) & C39 -> Refueling Building Walls | E39: standard | K39: =721.21*1.53 -> 1103.4513 | L39: $/m^3 | M39: Refueling Building Exterior Walls Volume | O39: m^3 | Q39: 2024 | R39: Lab and Mat and Equip | W39: Onsite Learning | X39: =0.9*$J39 -> 0 | Y39: =1.5*J39 -> 0 | Z39: Lognormal | AA39: =0.9*K39 -> 993.10617 | AB39: =1.3*K39 -> 1434.4867 | AC39: Lognormal | AD39: 0.1 | AE39: 1 | AF39: 0 | AG39: Truncated Normal
A40: 214.12 | B40: =IF(ISNUMBER(A40), IF(AND(A40=INT(A40), MOD(A40, 10) = 0), 0, IF(AND(A40=INT(A40), LEN(A40)=2), 1, IF(AND(A40=INT(A40), LEN(A40)=3), 2, LEN(A40) - FIND(".", A40) + 2) ) ), "") -> 4 | C40: Spent Fuel Building | D40: =REPT(" ", B40*2) & C40 -> Spent Fuel Building
...

Sheet MARVEL_Cost
A1: Account ID | B1: Account Title | C1: TOTAL COST (2024 USD)
A3: 10 | B3: Capitalized Pre-Construction Costs | C3: =C4 -> 5210451
A4: 15 | B4: Plant Studies | C4: 5210451
A5: 20 | B5: Capitalized Direct Costs | C5: =C6+C13+C45+C48+C52+C54 -> 30295715
A6: 21 | B6: Structures and Improvements | C6: =C7+C8+C9+C10 -> 2799006.7
A7: 211 | B7: Site Preparation/Yard Work
A8: 212 | B8: Reactor Island Civil Structures | C8: 2573469.9
A9: 213 | B9: Main Function Buildings
A10: 214 | B10: Buildings to Support Main Function | C10: =SUM(C11:C11) -> 225536.86
A11: 214.7 | B11: Emergency and Start-up Power Systems | C11: 225536.86
A12: 217 | B12: Miscellaneous Other Structures
A13: 22 | B13: Reactor System | C13: =C14+C32+C41+C42+C43+C44 -> 17586713
A14: 221 | B14: Reactor Components | C14: =C15+C19+C25 -> 8937296.6
A15: 221.1 | B15: Reactor vessel and accessories | C15: =C16+C17+C18 -> 2004852
A16: 221.11 | B16: Reactor support | C16: 762382.4
A17: 221.12 | B17: Outer vessel structure | C17: 1201688.6
A18: 221.13 | B18: Inner vessel structure | C18: 40781
A19: 221.2 | B19: Reactor control devices | C19: =C20 -> 2114223
A20: 221.21 | B20: Reactivity control system | C20: =SUM(C21:C23) -> 2114223
A21: 221.211 | B21: Reactivity Control System Fabrication | C21: 1391560
A22: 221.212 | B22: Installation | C22: 322663
A23: 221.213 | B23: Control Drums Materials (Absorber) | C23: 400000
A24: 221.214 | B24: Control Drums Materials (Reflector)
A25: 221.3 | B25: Non-fuel core internals | C25: =C26+C30+C31 -> 4818221.6
A26: 221.31 | B26: Reflector | C26: 4170231
A27: 221.311 | B27: Reflector (Materials: BeO) | C27: 3200000
A28: 221.312 | B28: Reflector (Materials: Be Metal) | C28: 850000
A29: 221.313 | B29: Reflector (installation | C29: 120231
A30: 221.32 | B30: Shield | C30: 647990.6
A31: 221.33 | B31: Moderator | C31: 0
A32: 222 | B32: Main Heat Transport System | C32: =C33+C34+C38+C39+C40 -> 5908950.6
A33: 222.1 | B33: Fluid circulation drive system | C33: 0
A34: 222.2 | B34: Reactor Heat Hransfer Piping System | C34: 4890230.6
A35: 222.21 | B35: Reactor Heat Hransfer Piping System (Mat) | C35: 1520786
A36: 222.22 | B36: Reactor Heat Hransfer Piping System (Fabrication) | C36: 3341486
A37: 222.23 | B37: Reactor Heat Hransfer Piping System (Installation) | C37: 27958.6
A38: 222.3 | B38: Heat Exchangers | C38: 0
A39: 222.4 | B39: Pressurizer System | C39: 0
A40: 222.5 | B40: Initial Heat Transfer Fluid Inventory | C40: 1018720
A41: 224 | B41: Radioactive Byproduct Processing Systems
...

Sheet Design Variables
A1: Variable | B1: Value | C1: Units | D1: Description
A2: Overall System
A3: Thermal power | B3: 83 | C3: kWth | D3: —
A4: Electric Power | B4: 20 | C4: kWe
A5: Core outer radius | B5: 5.5 | C5: inches | D5: —
A6: Reflector outer radius | B6: 16.5 | C6: inches | D6: —
A7: Fuel
A8: Fuel mass | B8: 145.3 | C8: kg | D8: UZrH
A9: U Weight fraction | B9: 30 | C9: wt% | D9: U/UZrH
A10: U enrichment | B10: 19.75 | C10: wt% | D10: High-assay low-enriched uranium (HALEU)
A11: Pins | B11: 36 | C11: # | D11: —
A12: Reflector
A13: Outer reflector material | B13: BeO | C13: — | D13: 99% theoretical density
A14: Elements | B14: 124 | C14: # | D14: Quarter plates
A15: Reflector plate thickness | B15: 1 | C15: inches | D15: —
A16: Reflector plate volume | B16: 818.4 | C16: cm3/plate | D16: —
A17: Mass of BeO reflector | B17: 318 | C17: Kg
A18: Insert volume | B18: 570 | C18: cm3/plate | D18: —
A19: Mass of Be-metal reflector | B19: 0.019 | C19: MT | D19: —
A20: Control Elements
A21: Control drums | B21: 4 | C21: # | D21: —
A22: Shutdown rods | B22: 1 | C22: # | D22: —
A23: Control drum elements | B23: 124 | C23: # | D23: Discs
A24: Drum disc thickness | B24: 1 | C24: inches | D24: —
A25: Drum reflector volume | B25: 880.8 | C25: cm3/plate | D25: BeO 99%
A26: Mass of drum reflector | B26: 309 | C26: Kg | D26: —
A27: Drum poison volume | B27: 49.2 | C27: cm3/plate | D27: B4C
A28: Mass of drum poison | B28: 14 | C28: Kg | D28: —
A29: Mass of rod poison | B29: 14 | C29: Kg | D29: B4C
A30: Instruments and Controls
A31: Control cabinet | B31: 5 | D31: —
A32: Instrument cabinet | B32: 2 | D32: —
A33: Nuclear input/output (IO) | B33: 9 | D33: —
A34: Non-nuclear IO | B34: 213 | D34: —
A35: Stirling engine IO | B35: 48 | C35: — | D35: These should be excluded if there no stirling engine?
A36: TOTAL | B36: 277
A37: Shielding in Vessel
A38: Stainless Steel cans | B38: 54.2 | C38: Kg | D38: Stainless Steel cans of the boron carbide shielding material (SS316H)
A39: Gamma shield material | B39: 56.3 | C39: Kg | D39: Gamma shield material inside the guard vessel (of Tungsten)
A40: Neutron shield material in the guard vessel | B40: 39.7 | C40: Kg | D40: made of natural B4C powder and is located above the core (a donut around the core barrel)—
...

Sheet Inflation Adjustment
A1: Year | B1: General | C1: Labor | D1: Material | E1: Equipment | F1: Lab and Mat and Equip | G1: Lab and Equip
A2: 1985 | B2: 2.4640874 | C2: 3.1848907 | D2: 3.0544914 | E2: 3.8305631 | F2: =(C2+D2+E2)/3 -> 3.3566484 | G2: =AVERAGE(C2,E2) -> 3.5077269
A3: =+A2+1 -> 1986 | B3: 2.4153374 | C3: 3.0852191 | D3: 3.0606568 | E3: 3.7330963 | F3: =(C3+D3+E3)/3 -> 3.2929907 | G3: =AVERAGE(C3,E3) -> 3.4091577
A4: =+A3+1 -> 1987 | B4: 2.3571109 | C4: 2.9915966 | D4: 2.9991875 | E4: 3.6990765 | F4: =(C4+D4+E4)/3 -> 3.2299536 | G4: =AVERAGE(C4,E4) -> 3.3453366
A5: =+A4+1 -> 1988 | B5: 2.2768417 | C5: 2.8748318 | D5: 2.8405735 | E5: 3.5245615 | F5: =(C5+D5+E5)/3 -> 3.0799889 | G5: =AVERAGE(C5,E5) -> 3.1996966
A6: =+A5+1 -> 1989 | B6: 2.1907944 | C6: 2.78125 | D6: 2.7498305 | E6: 3.3126659 | F6: =(C6+D6+E6)/3 -> 2.9479155 | G6: =AVERAGE(C6,E6) -> 3.046958
A7: =+A6+1 -> 1990 | B7: 2.1115837 | C7: 2.6589212 | D7: 2.7465738 | E7: 3.2240826 | F7: =(C7+D7+E7)/3 -> 2.8765258 | G7: =AVERAGE(C7,E7) -> 2.9415019
A8: =+A7+1 -> 1991 | B8: 2.0426379 | C8: 2.5540056 | D8: 2.7290821 | E8: 3.1182024 | F8: =(C8+D8+E8)/3 -> 2.80043 | G8: =AVERAGE(C8,E8) -> 2.836104
A9: =+A8+1 -> 1992 | B9: 1.9971771 | C9: 2.4750869 | D9: 2.6817441 | E9: 2.9899601 | F9: =(C9+D9+E9)/3 -> 2.715597 | G9: =AVERAGE(C9,E9) -> 2.7325235
A10: =+A9+1 -> 1993 | B10: 1.9508958 | C10: 2.3964099 | D10: 2.5547123 | E10: 2.8240631 | F10: =(C10+D10+E10)/3 -> 2.5917284 | G10: =AVERAGE(C10,E10) -> 2.6102365
A11: =+A10+1 -> 1994 | B11: 1.9101281 | C11: 2.3108547 | D11: 2.4545088 | E11: 2.7417224 | F11: =(C11+D11+E11)/3 -> 2.5023619 | G11: =AVERAGE(C11,E11) -> 2.5262885
A12: =+A11+1 -> 1995 | B12: 1.8708477 | C12: 2.27073 | D12: 2.3662637 | E12: 2.6948515 | F12: =(C12+D12+E12)/3 -> 2.4439484 | G12: =AVERAGE(C12,E12) -> 2.4827907
A13: =+A12+1 -> 1996 | B13: 1.8372585 | C13: 2.2150017 | D13: 2.3528479 | E13: 2.6375049 | F13: =(C13+D13+E13)/3 -> 2.4017848 | G13: =AVERAGE(C13,E13) -> 2.4262533
A14: =+A13+1 -> 1997 | B14: 1.8060906 | C14: 2.1583025 | D14: 2.3124125 | E14: 2.5759924 | F14: =(C14+D14+E14)/3 -> 2.3489024 | G14: =AVERAGE(C14,E14) -> 2.3671474
... A39: =+A38+1 -> 2022 | B39: 1.0615669 | C39: 1.0737265 | D39: 0.96194441 | E39: 1.0847449 | F39: =(C39+D39+E39)/3 -> 1.0401386 | G39: =AVERAGE(C39,E39) -> 1.0792357
A40: 2023 | B40: 1.0242342 | C40: 1.029563 | D40: 0.9902105 | E40: 1.0049167 | F40: =(C40+D40+E40)/3 -> 1.0082301 | G40: =AVERAGE(C40,E40) -> 1.0172399
A41: 2024 | B41: 1 | C41: 1 | D41: 1 | E41: 1 | F41: =(C41+D41+E41)/3 -> 1 | G41: =AVERAGE(C41,E41) -> 1

Sheet Economics Parameters
A1: Parameter | B1: Value | C1: Note | D1: Reference | E1: Notes
A2: indirect to direct field-related cost | B2: 0.065389932
A3: FTEs Per Onsite Operator (24/7) | B3: 5
A4: FTEs Per Offsite Operator (24/7) | B4: 5
A5: FTEs Per Security Staff (24/7) | B5: 5
A6: Hours Per FTE | B6: 1800
A7: Work Hours Per Shift | B7: 10
A8: Maintenance to Direct Cost Ratio | B8: 0.01
A9: Onsite Learning | B9: 0.08 | C9: FOAK to NOAK Learning Rates | D9: Assessment of Factory Fabrication Considerations for Nuclear Microreactors 10.1080/00295450.2023.2206779 | E9: Calculated based on Refernce Paper + Gyutae's work. Refer to TEM Slides for rationale and methodology
A10: No Learning | B10: 0
A11: Licensing Learning | B11: 0
A12: Factory Primary Structure | B12: 0.1844317
A13: Factory Drums | B13: 0.24138
A14: Factory Other | B14: 0.22962848
A15: Factory Be | B15: 0.41505378
A16: Factory BeO | B16: 0.39914906
A17: Non-nuclear off-the-shelf | B17: 0.05 | D17: Park, et al., Bottom-up levelized cost estimation of low-enriched and low-pressure nuclear batteries. Nuclear Engineering and Design. 2025. | E17: For off-the-shelf commercial components that are not produced in the FB Factory
